<sdf version='1.7'>
  <world name='default'>
    <light name='sun' type='directional'>
      <cast_shadows>1</cast_shadows>
      <pose>0 0 10 0 -0 0</pose>
      <diffuse>0.8 0.8 0.8 1</diffuse>
      <specular>0.2 0.2 0.2 1</specular>
      <attenuation>
        <range>1000</range>
        <constant>0.9</constant>
        <linear>0.01</linear>
        <quadratic>0.001</quadratic>
      </attenuation>
      <direction>-0.5 0.1 -0.9</direction>
      <spot>
        <inner_angle>0</inner_angle>
        <outer_angle>0</outer_angle>
        <falloff>0</falloff>
      </spot>
    </light>
    <model name='ground_plane'>
      <static>1</static>
      <link name='link'>
        <collision name='collision'>
          <geometry>
            <plane>
              <normal>0 0 1</normal>
              <size>100 100</size>
            </plane>
          </geometry>
          <surface>
            <friction>
              <ode>
                <mu>100</mu>
                <mu2>50</mu2>
              </ode>
              <torsional>
                <ode/>
              </torsional>
            </friction>
            <contact>
              <ode/>
            </contact>
            <bounce/>
          </surface>
          <max_contacts>10</max_contacts>
        </collision>
        <visual name='visual'>
          <cast_shadows>0</cast_shadows>
          <geometry>
            <plane>
              <normal>0 0 1</normal>
              <size>100 100</size>
            </plane>
          </geometry>
          <material>
            <script>
              <uri>file://media/materials/scripts/gazebo.material</uri>
              <name>Gazebo/Grey</name>
            </script>
          </material>
        </visual>
        <self_collide>0</self_collide>
        <enable_wind>0</enable_wind>
        <kinematic>0</kinematic>
      </link>
    </model>
    <gravity>0 0 -9.8</gravity>
    <magnetic_field>6e-06 2.3e-05 -4.2e-05</magnetic_field>
    <atmosphere type='adiabatic'/>
    <physics type='ode'>
      <max_step_size>0.001</max_step_size>
      <real_time_factor>1</real_time_factor>
      <real_time_update_rate>1000</real_time_update_rate>
    </physics>
    <scene>
      <ambient>0.4 0.4 0.4 1</ambient>
      <background>0.7 0.7 0.7 1</background>
      <shadows>1</shadows>
    </scene>
    <audio>
      <device>default</device>
    </audio>
    <wind/>
    <spherical_coordinates>
      <surface_model>EARTH_WGS84</surface_model>
      <latitude_deg>0</latitude_deg>
      <longitude_deg>0</longitude_deg>
      <elevation>0</elevation>
      <heading_deg>0</heading_deg>
    </spherical_coordinates>
    <state world_name='default'>
      <sim_time>2503 582000000</sim_time>
      <real_time>312 347401025</real_time>
      <wall_time>1733473074 777141434</wall_time>
      <iterations>271556</iterations>
      <model name='carport1'>
        <pose>-6.20477 6.33377 0 0 -0 0</pose>
        <scale>1 1 1</scale>
        <link name='Wall_105'>
          <pose>-9.67884 3.04727 0 0 -0 0</pose>
          <velocity>0 0 0 0 -0 0</velocity>
          <acceleration>0 0 0 0 -0 0</acceleration>
          <wrench>0 0 0 0 -0 0</wrench>
        </link>
        <link name='Wall_116'>
          <pose>-9.02784 4.59527 0 0 -0 1.5708</pose>
          <velocity>0 0 0 0 -0 0</velocity>
          <acceleration>0 0 0 0 -0 0</acceleration>
          <wrench>0 0 0 0 -0 0</wrench>
        </link>
        <link name='Wall_124'>
          <pose>-2.50084 4.60327 0 0 -0 1.5708</pose>
          <velocity>0 0 0 0 -0 0</velocity>
          <acceleration>0 0 0 0 -0 0</acceleration>
          <wrench>0 0 0 0 -0 0</wrench>
        </link>
        <link name='Wall_146'>
          <pose>-5.76434 7.07427 0 0 -0 0.001226</pose>
          <velocity>0 0 0 0 -0 0</velocity>
          <acceleration>0 0 0 0 -0 0</acceleration>
          <wrench>0 0 0 0 -0 0</wrench>
        </link>
        <link name='Wall_168'>
          <pose>-6.85304 4.59538 0 0 -0 1.57088</pose>
          <velocity>0 0 0 0 -0 0</velocity>
          <acceleration>0 0 0 0 -0 0</acceleration>
          <wrench>0 0 0 0 -0 0</wrench>
        </link>
        <link name='Wall_173'>
          <pose>-4.67804 4.59538 0 0 -0 1.57088</pose>
          <velocity>0 0 0 0 -0 0</velocity>
          <acceleration>0 0 0 0 -0 0</acceleration>
          <wrench>0 0 0 0 -0 0</wrench>
        </link>
        <link name='Wall_177'>
          <pose>-9.67884 3.04727 0 0 -0 0</pose>
          <velocity>0 0 0 0 -0 0</velocity>
          <acceleration>0 0 0 0 -0 0</acceleration>
          <wrench>0 0 0 0 -0 0</wrench>
        </link>
        <link name='Wall_179'>
          <pose>-8.85284 2.12027 0 0 -0 0</pose>
          <velocity>0 0 0 0 -0 0</velocity>
          <acceleration>0 0 0 0 -0 0</acceleration>
          <wrench>0 0 0 0 -0 0</wrench>
        </link>
        <link name='Wall_181'>
          <pose>-7.02784 2.12027 0 0 -0 3.14159</pose>
          <velocity>0 0 0 0 -0 0</velocity>
          <acceleration>0 0 0 0 -0 0</acceleration>
          <wrench>0 0 0 0 -0 0</wrench>
        </link>
        <link name='Wall_183'>
          <pose>-6.67784 2.12027 0 0 -0 0</pose>
          <velocity>0 0 0 0 -0 0</velocity>
          <acceleration>0 0 0 0 -0 0</acceleration>
          <wrench>0 0 0 0 -0 0</wrench>
        </link>
        <link name='Wall_185'>
          <pose>-4.85284 2.12027 0 0 -0 3.14159</pose>
          <velocity>0 0 0 0 -0 0</velocity>
          <acceleration>0 0 0 0 -0 0</acceleration>
          <wrench>0 0 0 0 -0 0</wrench>
        </link>
        <link name='Wall_187'>
          <pose>-4.50284 2.12027 0 0 -0 0</pose>
          <velocity>0 0 0 0 -0 0</velocity>
          <acceleration>0 0 0 0 -0 0</acceleration>
          <wrench>0 0 0 0 -0 0</wrench>
        </link>
        <link name='Wall_189'>
          <pose>-2.67584 2.12827 0 0 -0 3.14159</pose>
          <velocity>0 0 0 0 -0 0</velocity>
          <acceleration>0 0 0 0 -0 0</acceleration>
          <wrench>0 0 0 0 -0 0</wrench>
        </link>
      </model>
      <model name='carport1_clone_1'>
        <pose>-6.21434 -5.82325 0 0 -0 3.13851</pose>
        <scale>1 1 1</scale>
        <link name='Wall_105'>
          <pose>-2.73016 -2.54747 0 0 -0 3.13851</pose>
          <velocity>0 0 0 0 -0 0</velocity>
          <acceleration>0 0 0 0 -0 0</acceleration>
          <wrench>0 0 0 0 -0 0</wrench>
        </link>
        <link name='Wall_116'>
          <pose>-3.38593 -4.09346 0 0 0 -1.57387</pose>
          <velocity>0 0 0 0 -0 0</velocity>
          <acceleration>0 0 0 0 -0 0</acceleration>
          <wrench>0 0 0 0 -0 0</wrench>
        </link>
        <link name='Wall_124'>
          <pose>-9.91292 -4.08134 0 0 0 -1.57387</pose>
          <velocity>0 0 0 0 -0 0</velocity>
          <acceleration>0 0 0 0 -0 0</acceleration>
          <wrench>0 0 0 0 -0 0</wrench>
        </link>
        <link name='Wall_146'>
          <pose>-6.65705 -6.56239 0 0 -0 3.13974</pose>
          <velocity>0 0 0 0 -0 0</velocity>
          <acceleration>0 0 0 0 -0 0</acceleration>
          <wrench>0 0 0 0 -0 0</wrench>
        </link>
        <link name='Wall_168'>
          <pose>-5.56072 -4.08687 0 0 0 -1.57379</pose>
          <velocity>0 0 0 0 -0 0</velocity>
          <acceleration>0 0 0 0 -0 0</acceleration>
          <wrench>0 0 0 0 -0 0</wrench>
        </link>
        <link name='Wall_173'>
          <pose>-7.73571 -4.08016 0 0 0 -1.57379</pose>
          <velocity>0 0 0 0 -0 0</velocity>
          <acceleration>0 0 0 0 -0 0</acceleration>
          <wrench>0 0 0 0 -0 0</wrench>
        </link>
        <link name='Wall_177'>
          <pose>-2.73016 -2.54747 0 0 -0 3.13851</pose>
          <velocity>0 0 0 0 -0 0</velocity>
          <acceleration>0 0 0 0 -0 0</acceleration>
          <wrench>0 0 0 0 -0 0</wrench>
        </link>
        <link name='Wall_179'>
          <pose>-3.5533 -1.61793 0 0 -0 3.13851</pose>
          <velocity>0 0 0 0 -0 0</velocity>
          <acceleration>0 0 0 0 -0 0</acceleration>
          <wrench>0 0 0 0 -0 0</wrench>
        </link>
        <link name='Wall_181'>
          <pose>-5.37829 -1.61231 0 0 0 -0.003084</pose>
          <velocity>0 0 0 0 -0 0</velocity>
          <acceleration>0 0 0 0 -0 0</acceleration>
          <wrench>0 0 0 0 -0 0</wrench>
        </link>
        <link name='Wall_183'>
          <pose>-5.72829 -1.61123 0 0 -0 3.13851</pose>
          <velocity>0 0 0 0 -0 0</velocity>
          <acceleration>0 0 0 0 -0 0</acceleration>
          <wrench>0 0 0 0 -0 0</wrench>
        </link>
        <link name='Wall_185'>
          <pose>-7.55328 -1.6056 0 0 0 -0.003084</pose>
          <velocity>0 0 0 0 -0 0</velocity>
          <acceleration>0 0 0 0 -0 0</acceleration>
          <wrench>0 0 0 0 -0 0</wrench>
        </link>
        <link name='Wall_187'>
          <pose>-7.90328 -1.60453 0 0 -0 3.13851</pose>
          <velocity>0 0 0 0 -0 0</velocity>
          <acceleration>0 0 0 0 -0 0</acceleration>
          <wrench>0 0 0 0 -0 0</wrench>
        </link>
        <link name='Wall_189'>
          <pose>-9.7303 -1.6069 0 0 0 -0.003084</pose>
          <velocity>0 0 0 0 -0 0</velocity>
          <acceleration>0 0 0 0 -0 0</acceleration>
          <wrench>0 0 0 0 -0 0</wrench>
        </link>
      </model>
      <model name='ground_plane'>
        <pose>0 0 0 0 -0 0</pose>
        <scale>1 1 1</scale>
        <link name='link'>
          <pose>0 0 0 0 -0 0</pose>
          <velocity>0 0 0 0 -0 0</velocity>
          <acceleration>0 0 0 0 -0 0</acceleration>
          <wrench>0 0 0 0 -0 0</wrench>
        </link>
      </model>
      <model name='hatchback_red'>
        <pose>-4.47837 -4.03063 0 0 -0 1.57468</pose>
        <scale>1 1 1</scale>
        <link name='link'>
          <pose>-4.47837 -4.03063 0 0 -0 1.57468</pose>
          <velocity>0 0 0 0 -0 0</velocity>
          <acceleration>0 0 0 0 -0 0</acceleration>
          <wrench>0 0 0 0 -0 0</wrench>
        </link>
      </model>
      <model name='prius_hybrid'>
        <pose>-7.9081 4.47017 0.011641 -2e-06 -0 0.005264</pose>
        <scale>1 1 1</scale>
        <link name='chassis'>
          <pose>-7.9081 4.47017 0.011641 -2e-06 -0 0.005264</pose>
          <velocity>0 -0 2.1e-05 -3e-06 0 -1e-06</velocity>
          <acceleration>0 -0 -0 -1e-06 0 0</acceleration>
          <wrench>0 -0 -0 0 -0 0</wrench>
        </link>
        <link name='front_left_wheel'>
          <pose>-7.14069 3.06419 0.311646 -0.029664 0.066818 0.876086</pose>
          <velocity>-1e-06 1e-06 3.2e-05 -2e-06 -3e-06 0</velocity>
          <acceleration>0 -0 0 0 -0 0</acceleration>
          <wrench>0 -0 0 0 -0 0</wrench>
        </link>
        <link name='front_right_wheel'>
          <pose>-8.66067 3.05619 0.311646 -0.010608 0.057488 0.723149</pose>
          <velocity>-1e-06 2e-06 3.1e-05 -5e-06 -3e-06 1.7e-05</velocity>
          <acceleration>0 -0 -0 0 -0 0</acceleration>
          <wrench>0 -0 -0 0 -0 0</wrench>
        </link>
        <link name='rear_axle'>
          <pose>-7.91573 5.92015 0.311637 -2e-06 -4e-06 0.005264</pose>
          <velocity>1e-06 1e-06 1.5e-05 -4e-06 -4e-06 -1e-06</velocity>
          <acceleration>0 -0 -0 -0.00611 -3.2e-05 0</acceleration>
          <wrench>0 -0 -0 0 -0 0</wrench>
        </link>
        <link name='rear_left_wheel'>
          <pose>-7.12974 5.92428 0.311647 -0.057149 -3e-06 0.005264</pose>
          <velocity>1e-06 0 2.5e-05 -1e-06 -1e-06 -1e-06</velocity>
          <acceleration>0 -0 -0 0 -0 0</acceleration>
          <wrench>0 -0 -0 0 -0 0</wrench>
        </link>
        <link name='rear_right_wheel'>
          <pose>-8.70172 5.91601 0.311647 -0.031249 8e-06 0.005264</pose>
          <velocity>2e-06 2e-06 2.5e-05 -6e-06 2e-06 -1e-06</velocity>
          <acceleration>-0 -0 0 0 -0 0</acceleration>
          <wrench>-0 -0 0 0 -0 0</wrench>
        </link>
        <link name='steering_wheel'>
          <pose>-7.54907 3.84471 0.997957 -8.1e-05 1.30202 1.57606</pose>
          <velocity>-0 3e-06 2.3e-05 -3e-06 0 -1e-06</velocity>
          <acceleration>-0 -0 -0 0 -0 0</acceleration>
          <wrench>-0 -0 -0 0 -0 0</wrench>
        </link>
      </model>
      <model name='suv'>
        <pose>-3.71509 4.70413 0 0 0 -1.56794</pose>
        <scale>1 1 1</scale>
        <link name='link'>
          <pose>-3.71509 4.70413 0 0 0 -1.56794</pose>
          <velocity>0 0 0 0 -0 0</velocity>
          <acceleration>0 0 0 0 -0 0</acceleration>
          <wrench>0 0 0 0 -0 0</wrench>
        </link>
      </model>
      <model name='tb1'>
        <pose>-1.49196 -0.49994 0.007807 2.9e-05 0.00669 0.014874</pose>
        <scale>1 1 1</scale>
        <link name='base_footprint'>
          <pose>-1.49196 -0.49994 0.007807 2.9e-05 0.00669 0.014874</pose>
          <velocity>-2.8e-05 -6e-05 -0.090111 -7.2e-05 0.00237 4.9e-05</velocity>
          <acceleration>-0.004541 -4.2e-05 1.28764 0.007685 0.319123 -9.9e-05</acceleration>
          <wrench>-0.004541 -4.2e-05 1.28764 0 -0 0</wrench>
        </link>
        <link name='base_link'>
          <pose>-1.49196 -0.49994 0.007807 2.9e-05 0.006691 0.014874</pose>
          <velocity>1.7e-05 -6e-05 -0.090061 -7.2e-05 0.002142 4.9e-05</velocity>
          <acceleration>0.010804 -0.000341 1.30794 0.008138 0.319956 -0.000136</acceleration>
          <wrench>0.014833 -0.000468 1.79568 0 -0 0</wrench>
        </link>
        <link name='base_scan'>
          <pose>-1.49196 -0.49994 0.007807 2.9e-05 0.006684 0.014874</pose>
          <velocity>-3.2e-05 -6e-05 -0.090174 -7.9e-05 0.003202 4.9e-05</velocity>
          <acceleration>0.031214 -0.000872 1.30443 0.008532 0.325255 -9.2e-05</acceleration>
          <wrench>0.003558 -9.9e-05 0.148705 0 -0 0</wrench>
        </link>
        <link name='camera_link'>
          <pose>-1.49196 -0.49994 0.007807 2.9e-05 0.006686 0.014874</pose>
          <velocity>-2.7e-05 -6e-05 -0.090152 -7.7e-05 0.002959 4.9e-05</velocity>
          <acceleration>-0.004942 6.6e-05 1.28775 0.008461 0.323978 -9.4e-05</acceleration>
          <wrench>-0.004942 6.6e-05 1.28775 0 -0 0</wrench>
        </link>
        <link name='camera_rgb_frame'>
          <pose>-1.42156 -0.545901 0.114342 2.9e-05 0.006686 0.014874</pose>
          <velocity>0.000304 -4.2e-05 -0.090421 -0.000106 0.002936 4.3e-05</velocity>
          <acceleration>0.064202 -0.001797 1.24173 0.008704 0.3245 -9.9e-05</acceleration>
          <wrench>0.002247 -6.3e-05 0.043461 0 -0 0</wrench>
        </link>
        <link name='caster_back_left_link'>
          <pose>-1.66992 -0.43858 0.004988 1.2692 -0.187978 -0.676326</pose>
          <velocity>-1.7e-05 -5e-05 -0.038791 0.009959 -0.003436 0</velocity>
          <acceleration>0.000144 2e-06 0.646771 0.019505 0.017575 0</acceleration>
          <wrench>0 0 0.000647 0 -0 0</wrench>
        </link>
        <link name='caster_back_right_link'>
          <pose>-1.66801 -0.566566 0.004985 0.823802 -0.360824 -0.656141</pose>
          <velocity>-1.5e-05 -4.1e-05 -0.038731 0.008114 -0.003106 0</velocity>
          <acceleration>0.000156 0.00018 0.690441 -0.021913 0.017124 -0</acceleration>
          <wrench>0 0 0.00069 0 -0 0</wrench>
        </link>
        <link name='imu_link'>
          <pose>-1.49196 -0.49994 0.007807 2.9e-05 0.006685 0.014874</pose>
          <velocity>-1.7e-05 -6e-05 -0.090162 -7e-05 0.002809 4.9e-05</velocity>
          <acceleration>-0.004908 -1.6e-05 1.28812 0.006833 0.323016 -7.9e-05</acceleration>
          <wrench>-0.004908 -1.6e-05 1.28812 0 -0 0</wrench>
        </link>
        <link name='wheel_left_link'>
          <pose>-1.49599 -0.500001 0.008193 3.6e-05 0.183781 0.015021</pose>
          <velocity>1.1e-05 -1.6e-05 -0.090358 0.001563 0.001533 -3.4e-05</velocity>
          <acceleration>0.003946 -0.000188 1.28945 0.007194 0.119377 -0.007806</acceleration>
          <wrench>0.000395 -1.9e-05 0.128945 0 -0 0</wrench>
        </link>
        <link name='wheel_right_link'>
          <pose>-1.49893 -0.500045 0.008932 6.4e-05 0.313514 0.015135</pose>
          <velocity>2.7e-05 -1.7e-05 -0.08988 0.00158 0.001962 -3.5e-05</velocity>
          <acceleration>0.003895 -0.00017 1.28629 0.006638 0.117846 -0.007828</acceleration>
          <wrench>0.00039 -1.7e-05 0.12863 0 -0 0</wrench>
        </link>
      </model>
      <model name='tb2'>
        <pose>-1.49203 0.500059 0.007806 3.6e-05 0.006688 0.014757</pose>
        <scale>1 1 1</scale>
        <link name='base_footprint'>
          <pose>-1.49203 0.500059 0.007806 3.6e-05 0.006688 0.014757</pose>
          <velocity>-2.8e-05 -5.9e-05 -0.090222 -4e-06 0.00231 4.9e-05</velocity>
          <acceleration>-0.00463 0.000115 1.30172 0.007502 0.319808 -9e-05</acceleration>
          <wrench>-0.00463 0.000115 1.30172 0 -0 0</wrench>
        </link>
        <link name='base_link'>
          <pose>-1.49203 0.500059 0.007806 3.6e-05 0.006689 0.014757</pose>
          <velocity>1.7e-05 -6e-05 -0.090172 -4e-06 0.002083 4.9e-05</velocity>
          <acceleration>0.010752 -0.000175 1.32206 0.007959 0.320623 -0.000125</acceleration>
          <wrench>0.014761 -0.00024 1.81508 0 -0 0</wrench>
        </link>
        <link name='base_scan'>
          <pose>-1.49203 0.500059 0.007807 3.6e-05 0.006682 0.014757</pose>
          <velocity>-3.3e-05 -6e-05 -0.090286 -8e-06 0.003142 4.9e-05</velocity>
          <acceleration>0.031217 -0.000695 1.31856 0.008374 0.326126 -8.4e-05</acceleration>
          <wrench>0.003559 -7.9e-05 0.150316 0 -0 0</wrench>
        </link>
        <link name='camera_link'>
          <pose>-1.49203 0.500059 0.007806 3.6e-05 0.006684 0.014757</pose>
          <velocity>-2.7e-05 -6e-05 -0.090264 -7e-06 0.0029 4.9e-05</velocity>
          <acceleration>-0.005036 0.000226 1.30184 0.008298 0.324801 -8.5e-05</acceleration>
          <wrench>-0.005036 0.000226 1.30184 0 -0 0</wrench>
        </link>
        <link name='camera_rgb_frame'>
          <pose>-1.42163 0.454089 0.114341 3.6e-05 0.006684 0.014757</pose>
          <velocity>0.000297 -4.9e-05 -0.090531 -3.6e-05 0.002876 4.3e-05</velocity>
          <acceleration>0.06429 -0.001601 1.25572 0.008545 0.325332 -9.1e-05</acceleration>
          <wrench>0.00225 -5.6e-05 0.04395 0 -0 0</wrench>
        </link>
        <link name='caster_back_left_link'>
          <pose>-1.66997 0.56144 0.004988 1.22396 -0.156659 -0.688081</pose>
          <velocity>-1.7e-05 -5.1e-05 -0.038857 0.010132 -0.003541 0</velocity>
          <acceleration>0.000156 6.1e-05 0.648464 0.00845 0.020007 -0</acceleration>
          <wrench>0 0 0.000648 0 -0 0</wrench>
        </link>
        <link name='caster_back_right_link'>
          <pose>-1.66809 0.433454 0.004984 0.787823 -0.328114 -0.691183</pose>
          <velocity>-1.6e-05 -4.2e-05 -0.038809 0.008395 -0.003225 0</velocity>
          <acceleration>0.000172 0.000281 0.692559 -0.040932 0.020294 0</acceleration>
          <wrench>0 0 0.000693 0 -0 0</wrench>
        </link>
        <link name='imu_link'>
          <pose>-1.49203 0.500059 0.007806 3.6e-05 0.006684 0.014757</pose>
          <velocity>-1.7e-05 -6e-05 -0.090273 -0 0.002749 4.9e-05</velocity>
          <acceleration>-0.005003 0.000143 1.30221 0.00665 0.323871 -7e-05</acceleration>
          <wrench>-0.005003 0.000143 1.30221 0 -0 0</wrench>
        </link>
        <link name='wheel_left_link'>
          <pose>-1.49602 0.499999 0.008186 4.3e-05 0.182349 0.014904</pose>
          <velocity>1.1e-05 -1.7e-05 -0.090466 0.001611 0.001481 -3.4e-05</velocity>
          <acceleration>0.003878 -4.1e-05 1.30351 0.002704 0.11728 -0.007902</acceleration>
          <wrench>0.000388 -4e-06 0.130351 0 -0 0</wrench>
        </link>
        <link name='wheel_right_link'>
          <pose>-1.49894 0.499956 0.008914 7.1e-05 0.311056 0.015017</pose>
          <velocity>2.6e-05 -1.8e-05 -0.089995 0.001628 0.001911 -3.5e-05</velocity>
          <acceleration>0.00383 -2.2e-05 1.30041 0.002126 0.115821 -0.007922</acceleration>
          <wrench>0.000383 -2e-06 0.130041 0 -0 0</wrench>
        </link>
      </model>
      <model name='wall_L'>
        <pose>-5.55088 0.58686 0 0 -0 0</pose>
        <scale>1 1 1</scale>
        <link name='Wall_12'>
          <pose>-6.22676 -6.98814 0 0 -0 3.14159</pose>
          <velocity>0 0 0 0 -0 0</velocity>
          <acceleration>0 0 0 0 -0 0</acceleration>
          <wrench>0 0 0 0 -0 0</wrench>
        </link>
        <link name='Wall_14'>
          <pose>-11.0268 0.611859 0 0 0 -1.5708</pose>
          <velocity>0 0 0 0 -0 0</velocity>
          <acceleration>0 0 0 0 -0 0</acceleration>
          <wrench>0 0 0 0 -0 0</wrench>
        </link>
        <link name='Wall_16'>
          <pose>-1.42676 -4.18814 0 0 -0 1.5708</pose>
          <velocity>0 0 0 0 -0 0</velocity>
          <acceleration>0 0 0 0 -0 0</acceleration>
          <wrench>0 0 0 0 -0 0</wrench>
        </link>
        <link name='Wall_18'>
          <pose>-1.42676 5.61186 0 0 0 -1.5708</pose>
          <velocity>0 0 0 0 -0 0</velocity>
          <acceleration>0 0 0 0 -0 0</acceleration>
          <wrench>0 0 0 0 -0 0</wrench>
        </link>
        <link name='Wall_7'>
          <pose>-6.22676 8.16186 0 0 -0 0</pose>
          <velocity>0 0 0 0 -0 0</velocity>
          <acceleration>0 0 0 0 -0 0</acceleration>
          <wrench>0 0 0 0 -0 0</wrench>
        </link>
      </model>
      <light name='sun'>
        <pose>0 0 10 0 -0 0</pose>
      </light>
    </state>
    <gui fullscreen='0'>
      <camera name='user_camera'>
        <pose>2.85295 9.31717 11.2502 -0 0.773798 -2.40587</pose>
        <view_controller>orbit</view_controller>
        <projection_type>perspective</projection_type>
      </camera>
    </gui>
    <model name='carport1'>
      <pose>-1.00393 -4.2885 0 0 -0 0</pose>
      <link name='Wall_105'>
        <collision name='Wall_105_Collision'>
          <geometry>
            <box>
              <size>0.61 0.6 1.5</size>
            </box>
          </geometry>
          <pose>0 0 0.75 0 -0 0</pose>
          <max_contacts>10</max_contacts>
          <surface>
            <contact>
              <ode/>
            </contact>
            <bounce/>
            <friction>
              <torsional>
                <ode/>
              </torsional>
              <ode/>
            </friction>
          </surface>
        </collision>
        <visual name='Wall_105_Visual'>
          <pose>0 0 0.75 0 -0 0</pose>
          <geometry>
            <box>
              <size>0.61 0.6 1.5</size>
            </box>
          </geometry>
          <material>
            <script>
              <uri>file://media/materials/scripts/gazebo.material</uri>
              <name>Gazebo/Grey</name>
            </script>
            <ambient>1 1 1 1</ambient>
          </material>
          <meta>
            <layer>0</layer>
          </meta>
        </visual>
        <pose>-3.47407 -3.2865 0 0 -0 0</pose>
        <self_collide>0</self_collide>
        <enable_wind>0</enable_wind>
        <kinematic>0</kinematic>
      </link>
      <link name='Wall_116'>
        <collision name='Wall_116_Collision'>
          <geometry>
            <box>
              <size>5.1 0.15 0.005</size>
            </box>
          </geometry>
          <pose>0 0 0.0025 0 -0 0</pose>
          <max_contacts>10</max_contacts>
          <surface>
            <contact>
              <ode/>
            </contact>
            <bounce/>
            <friction>
              <torsional>
                <ode/>
              </torsional>
              <ode/>
            </friction>
          </surface>
        </collision>
        <visual name='Wall_116_Visual'>
          <pose>0 0 0.0025 0 -0 0</pose>
          <geometry>
            <box>
              <size>5.1 0.15 0.005</size>
            </box>
          </geometry>
          <material>
            <script>
              <uri>file://media/materials/scripts/gazebo.material</uri>
              <name>Gazebo/Grey</name>
            </script>
            <ambient>1 1 1 1</ambient>
          </material>
          <meta>
            <layer>0</layer>
          </meta>
        </visual>
        <pose>-2.82307 -1.7385 0 0 -0 1.5708</pose>
        <self_collide>0</self_collide>
        <enable_wind>0</enable_wind>
        <kinematic>0</kinematic>
      </link>
      <link name='Wall_124'>
        <collision name='Wall_124_Collision'>
          <geometry>
            <box>
              <size>5.1 0.15 0.005</size>
            </box>
          </geometry>
          <pose>0 0 0.0025 0 -0 0</pose>
          <max_contacts>10</max_contacts>
          <surface>
            <contact>
              <ode/>
            </contact>
            <bounce/>
            <friction>
              <torsional>
                <ode/>
              </torsional>
              <ode/>
            </friction>
          </surface>
        </collision>
        <visual name='Wall_124_Visual'>
          <pose>0 0 0.0025 0 -0 0</pose>
          <geometry>
            <box>
              <size>5.1 0.15 0.005</size>
            </box>
          </geometry>
          <material>
            <script>
              <uri>file://media/materials/scripts/gazebo.material</uri>
              <name>Gazebo/Grey</name>
            </script>
            <ambient>1 1 1 1</ambient>
          </material>
          <meta>
            <layer>0</layer>
          </meta>
        </visual>
        <pose>3.70393 -1.7305 0 0 -0 1.5708</pose>
        <self_collide>0</self_collide>
        <enable_wind>0</enable_wind>
        <kinematic>0</kinematic>
      </link>
      <link name='Wall_146'>
        <collision name='Wall_146_Collision'>
          <geometry>
            <box>
              <size>6.67711 0.15 0.005</size>
            </box>
          </geometry>
          <pose>0 0 0.0025 0 -0 0</pose>
          <max_contacts>10</max_contacts>
          <surface>
            <contact>
              <ode/>
            </contact>
            <bounce/>
            <friction>
              <torsional>
                <ode/>
              </torsional>
              <ode/>
            </friction>
          </surface>
        </collision>
        <visual name='Wall_146_Visual'>
          <pose>0 0 0.0025 0 -0 0</pose>
          <geometry>
            <box>
              <size>6.67711 0.15 0.005</size>
            </box>
          </geometry>
          <material>
            <script>
              <uri>file://media/materials/scripts/gazebo.material</uri>
              <name>Gazebo/Grey</name>
            </script>
            <ambient>1 1 1 1</ambient>
          </material>
          <meta>
            <layer>0</layer>
          </meta>
        </visual>
        <pose>0.440428 0.7405 0 0 -0 0.001226</pose>
        <self_collide>0</self_collide>
        <enable_wind>0</enable_wind>
        <kinematic>0</kinematic>
      </link>
      <link name='Wall_168'>
        <collision name='Wall_168_Collision'>
          <geometry>
            <box>
              <size>5.1 0.15 0.005</size>
            </box>
          </geometry>
          <pose>0 0 0.0025 0 -0 0</pose>
          <max_contacts>10</max_contacts>
          <surface>
            <contact>
              <ode/>
            </contact>
            <bounce/>
            <friction>
              <torsional>
                <ode/>
              </torsional>
              <ode/>
            </friction>
          </surface>
        </collision>
        <visual name='Wall_168_Visual'>
          <pose>0 0 0.0025 0 -0 0</pose>
          <geometry>
            <box>
              <size>5.1 0.15 0.005</size>
            </box>
          </geometry>
          <material>
            <script>
              <uri>file://media/materials/scripts/gazebo.material</uri>
              <name>Gazebo/Grey</name>
            </script>
            <ambient>1 1 1 1</ambient>
          </material>
          <meta>
            <layer>0</layer>
          </meta>
        </visual>
        <pose>-0.64827 -1.73839 0 0 -0 1.57088</pose>
        <self_collide>0</self_collide>
        <enable_wind>0</enable_wind>
        <kinematic>0</kinematic>
      </link>
      <link name='Wall_173'>
        <collision name='Wall_173_Collision'>
          <geometry>
            <box>
              <size>5.1 0.15 0.005</size>
            </box>
          </geometry>
          <pose>0 0 0.0025 0 -0 0</pose>
          <max_contacts>10</max_contacts>
          <surface>
            <contact>
              <ode/>
            </contact>
            <bounce/>
            <friction>
              <torsional>
                <ode/>
              </torsional>
              <ode/>
            </friction>
          </surface>
        </collision>
        <visual name='Wall_173_Visual'>
          <pose>0 0 0.0025 0 -0 0</pose>
          <geometry>
            <box>
              <size>5.1 0.15 0.005</size>
            </box>
          </geometry>
          <material>
            <script>
              <uri>file://media/materials/scripts/gazebo.material</uri>
              <name>Gazebo/Grey</name>
            </script>
            <ambient>1 1 1 1</ambient>
          </material>
          <meta>
            <layer>0</layer>
          </meta>
        </visual>
        <pose>1.52673 -1.73839 0 0 -0 1.57088</pose>
        <self_collide>0</self_collide>
        <enable_wind>0</enable_wind>
        <kinematic>0</kinematic>
      </link>
      <link name='Wall_177'>
        <collision name='Wall_177_Collision'>
          <geometry>
            <box>
              <size>0.6 0.59 3</size>
            </box>
          </geometry>
          <pose>0 0 1.5 0 -0 0</pose>
          <max_contacts>10</max_contacts>
          <surface>
            <contact>
              <ode/>
            </contact>
            <bounce/>
            <friction>
              <torsional>
                <ode/>
              </torsional>
              <ode/>
            </friction>
          </surface>
        </collision>
        <visual name='Wall_177_Visual'>
          <pose>0 0 1.5 0 -0 0</pose>
          <geometry>
            <box>
              <size>0.6 0.59 3</size>
            </box>
          </geometry>
          <material>
            <script>
              <uri>file://media/materials/scripts/gazebo.material</uri>
              <name>Gazebo/Grey</name>
            </script>
            <ambient>0.996078 0.47451 0.0196078 1</ambient>
          </material>
          <meta>
            <layer>0</layer>
          </meta>
        </visual>
        <pose>-3.47407 -3.2865 0 0 -0 0</pose>
        <self_collide>0</self_collide>
        <enable_wind>0</enable_wind>
        <kinematic>0</kinematic>
      </link>
      <link name='Wall_179'>
        <collision name='Wall_179_Collision'>
          <geometry>
            <box>
              <size>0.5 0.15 0.005</size>
            </box>
          </geometry>
          <pose>0 0 0.0025 0 -0 0</pose>
          <max_contacts>10</max_contacts>
          <surface>
            <contact>
              <ode/>
            </contact>
            <bounce/>
            <friction>
              <torsional>
                <ode/>
              </torsional>
              <ode/>
            </friction>
          </surface>
        </collision>
        <visual name='Wall_179_Visual'>
          <pose>0 0 0.0025 0 -0 0</pose>
          <geometry>
            <box>
              <size>0.5 0.15 0.005</size>
            </box>
          </geometry>
          <material>
            <script>
              <uri>file://media/materials/scripts/gazebo.material</uri>
              <name>Gazebo/Grey</name>
            </script>
            <ambient>1 1 1 1</ambient>
          </material>
          <meta>
            <layer>0</layer>
          </meta>
        </visual>
        <pose>-2.64807 -4.2135 0 0 -0 0</pose>
        <self_collide>0</self_collide>
        <enable_wind>0</enable_wind>
        <kinematic>0</kinematic>
      </link>
      <link name='Wall_181'>
        <collision name='Wall_181_Collision'>
          <geometry>
            <box>
              <size>0.5 0.15 0.005</size>
            </box>
          </geometry>
          <pose>0 0 0.0025 0 -0 0</pose>
          <max_contacts>10</max_contacts>
          <surface>
            <contact>
              <ode/>
            </contact>
            <bounce/>
            <friction>
              <torsional>
                <ode/>
              </torsional>
              <ode/>
            </friction>
          </surface>
        </collision>
        <visual name='Wall_181_Visual'>
          <pose>0 0 0.0025 0 -0 0</pose>
          <geometry>
            <box>
              <size>0.5 0.15 0.005</size>
            </box>
          </geometry>
          <material>
            <script>
              <uri>file://media/materials/scripts/gazebo.material</uri>
              <name>Gazebo/Grey</name>
            </script>
            <ambient>1 1 1 1</ambient>
          </material>
          <meta>
            <layer>0</layer>
          </meta>
        </visual>
        <pose>-0.823072 -4.2135 0 0 -0 3.14159</pose>
        <self_collide>0</self_collide>
        <enable_wind>0</enable_wind>
        <kinematic>0</kinematic>
      </link>
      <link name='Wall_183'>
        <collision name='Wall_183_Collision'>
          <geometry>
            <box>
              <size>0.5 0.15 0.005</size>
            </box>
          </geometry>
          <pose>0 0 0.0025 0 -0 0</pose>
          <max_contacts>10</max_contacts>
          <surface>
            <contact>
              <ode/>
            </contact>
            <bounce/>
            <friction>
              <torsional>
                <ode/>
              </torsional>
              <ode/>
            </friction>
          </surface>
        </collision>
        <visual name='Wall_183_Visual'>
          <pose>0 0 0.0025 0 -0 0</pose>
          <geometry>
            <box>
              <size>0.5 0.15 0.005</size>
            </box>
          </geometry>
          <material>
            <script>
              <uri>file://media/materials/scripts/gazebo.material</uri>
              <name>Gazebo/Grey</name>
            </script>
            <ambient>1 1 1 1</ambient>
          </material>
          <meta>
            <layer>0</layer>
          </meta>
        </visual>
        <pose>-0.473072 -4.2135 0 0 -0 0</pose>
        <self_collide>0</self_collide>
        <enable_wind>0</enable_wind>
        <kinematic>0</kinematic>
      </link>
      <link name='Wall_185'>
        <collision name='Wall_185_Collision'>
          <geometry>
            <box>
              <size>0.5 0.15 0.005</size>
            </box>
          </geometry>
          <pose>0 0 0.0025 0 -0 0</pose>
          <max_contacts>10</max_contacts>
          <surface>
            <contact>
              <ode/>
            </contact>
            <bounce/>
            <friction>
              <torsional>
                <ode/>
              </torsional>
              <ode/>
            </friction>
          </surface>
        </collision>
        <visual name='Wall_185_Visual'>
          <pose>0 0 0.0025 0 -0 0</pose>
          <geometry>
            <box>
              <size>0.5 0.15 0.005</size>
            </box>
          </geometry>
          <material>
            <script>
              <uri>file://media/materials/scripts/gazebo.material</uri>
              <name>Gazebo/Grey</name>
            </script>
            <ambient>1 1 1 1</ambient>
          </material>
          <meta>
            <layer>0</layer>
          </meta>
        </visual>
        <pose>1.35193 -4.2135 0 0 -0 3.14159</pose>
        <self_collide>0</self_collide>
        <enable_wind>0</enable_wind>
        <kinematic>0</kinematic>
      </link>
      <link name='Wall_187'>
        <collision name='Wall_187_Collision'>
          <geometry>
            <box>
              <size>0.5 0.15 0.005</size>
            </box>
          </geometry>
          <pose>0 0 0.0025 0 -0 0</pose>
          <max_contacts>10</max_contacts>
          <surface>
            <contact>
              <ode/>
            </contact>
            <bounce/>
            <friction>
              <torsional>
                <ode/>
              </torsional>
              <ode/>
            </friction>
          </surface>
        </collision>
        <visual name='Wall_187_Visual'>
          <pose>0 0 0.0025 0 -0 0</pose>
          <geometry>
            <box>
              <size>0.5 0.15 0.005</size>
            </box>
          </geometry>
          <material>
            <script>
              <uri>file://media/materials/scripts/gazebo.material</uri>
              <name>Gazebo/Grey</name>
            </script>
            <ambient>1 1 1 1</ambient>
          </material>
          <meta>
            <layer>0</layer>
          </meta>
        </visual>
        <pose>1.70193 -4.2135 0 0 -0 0</pose>
        <self_collide>0</self_collide>
        <enable_wind>0</enable_wind>
        <kinematic>0</kinematic>
      </link>
      <link name='Wall_189'>
        <collision name='Wall_189_Collision'>
          <geometry>
            <box>
              <size>0.5 0.15 0.005</size>
            </box>
          </geometry>
          <pose>0 0 0.0025 0 -0 0</pose>
          <max_contacts>10</max_contacts>
          <surface>
            <contact>
              <ode/>
            </contact>
            <bounce/>
            <friction>
              <torsional>
                <ode/>
              </torsional>
              <ode/>
            </friction>
          </surface>
        </collision>
        <visual name='Wall_189_Visual'>
          <pose>0 0 0.0025 0 -0 0</pose>
          <geometry>
            <box>
              <size>0.5 0.15 0.005</size>
            </box>
          </geometry>
          <material>
            <script>
              <uri>file://media/materials/scripts/gazebo.material</uri>
              <name>Gazebo/Grey</name>
            </script>
            <ambient>1 1 1 1</ambient>
          </material>
          <meta>
            <layer>0</layer>
          </meta>
        </visual>
        <pose>3.52893 -4.2055 0 0 -0 3.14159</pose>
        <self_collide>0</self_collide>
        <enable_wind>0</enable_wind>
        <kinematic>0</kinematic>
      </link>
      <static>1</static>
    </model>
    <model name='carport1_clone_1'>
      <pose>-3.36895 -4.5244 0 0 -0 0</pose>
      <link name='Wall_105'>
        <collision name='Wall_105_Collision'>
          <geometry>
            <box>
              <size>0.61 0.6 1.5</size>
            </box>
          </geometry>
          <pose>0 0 0.75 0 -0 0</pose>
          <max_contacts>10</max_contacts>
          <surface>
            <contact>
              <ode/>
            </contact>
            <bounce/>
            <friction>
              <torsional>
                <ode/>
              </torsional>
              <ode/>
            </friction>
          </surface>
        </collision>
        <visual name='Wall_105_Visual'>
          <pose>0 0 0.75 0 -0 0</pose>
          <geometry>
            <box>
              <size>0.61 0.6 1.5</size>
            </box>
          </geometry>
          <material>
            <script>
              <uri>file://media/materials/scripts/gazebo.material</uri>
              <name>Gazebo/Grey</name>
            </script>
            <ambient>1 1 1 1</ambient>
          </material>
          <meta>
            <layer>0</layer>
          </meta>
        </visual>
        <pose>-3.47407 -3.2865 0 0 -0 0</pose>
        <self_collide>0</self_collide>
        <enable_wind>0</enable_wind>
        <kinematic>0</kinematic>
      </link>
      <link name='Wall_116'>
        <collision name='Wall_116_Collision'>
          <geometry>
            <box>
              <size>5.1 0.15 0.005</size>
            </box>
          </geometry>
          <pose>0 0 0.0025 0 -0 0</pose>
          <max_contacts>10</max_contacts>
          <surface>
            <contact>
              <ode/>
            </contact>
            <bounce/>
            <friction>
              <torsional>
                <ode/>
              </torsional>
              <ode/>
            </friction>
          </surface>
        </collision>
        <visual name='Wall_116_Visual'>
          <pose>0 0 0.0025 0 -0 0</pose>
          <geometry>
            <box>
              <size>5.1 0.15 0.005</size>
            </box>
          </geometry>
          <material>
            <script>
              <uri>file://media/materials/scripts/gazebo.material</uri>
              <name>Gazebo/Grey</name>
            </script>
            <ambient>1 1 1 1</ambient>
          </material>
          <meta>
            <layer>0</layer>
          </meta>
        </visual>
        <pose>-2.82307 -1.7385 0 0 -0 1.5708</pose>
        <self_collide>0</self_collide>
        <enable_wind>0</enable_wind>
        <kinematic>0</kinematic>
      </link>
      <link name='Wall_124'>
        <collision name='Wall_124_Collision'>
          <geometry>
            <box>
              <size>5.1 0.15 0.005</size>
            </box>
          </geometry>
          <pose>0 0 0.0025 0 -0 0</pose>
          <max_contacts>10</max_contacts>
          <surface>
            <contact>
              <ode/>
            </contact>
            <bounce/>
            <friction>
              <torsional>
                <ode/>
              </torsional>
              <ode/>
            </friction>
          </surface>
        </collision>
        <visual name='Wall_124_Visual'>
          <pose>0 0 0.0025 0 -0 0</pose>
          <geometry>
            <box>
              <size>5.1 0.15 0.005</size>
            </box>
          </geometry>
          <material>
            <script>
              <uri>file://media/materials/scripts/gazebo.material</uri>
              <name>Gazebo/Grey</name>
            </script>
            <ambient>1 1 1 1</ambient>
          </material>
          <meta>
            <layer>0</layer>
          </meta>
        </visual>
        <pose>3.70393 -1.7305 0 0 -0 1.5708</pose>
        <self_collide>0</self_collide>
        <enable_wind>0</enable_wind>
        <kinematic>0</kinematic>
      </link>
      <link name='Wall_146'>
        <collision name='Wall_146_Collision'>
          <geometry>
            <box>
              <size>6.67711 0.15 0.005</size>
            </box>
          </geometry>
          <pose>0 0 0.0025 0 -0 0</pose>
          <max_contacts>10</max_contacts>
          <surface>
            <contact>
              <ode/>
            </contact>
            <bounce/>
            <friction>
              <torsional>
                <ode/>
              </torsional>
              <ode/>
            </friction>
          </surface>
        </collision>
        <visual name='Wall_146_Visual'>
          <pose>0 0 0.0025 0 -0 0</pose>
          <geometry>
            <box>
              <size>6.67711 0.15 0.005</size>
            </box>
          </geometry>
          <material>
            <script>
              <uri>file://media/materials/scripts/gazebo.material</uri>
              <name>Gazebo/Grey</name>
            </script>
            <ambient>1 1 1 1</ambient>
          </material>
          <meta>
            <layer>0</layer>
          </meta>
        </visual>
        <pose>0.440428 0.7405 0 0 -0 0.001226</pose>
        <self_collide>0</self_collide>
        <enable_wind>0</enable_wind>
        <kinematic>0</kinematic>
      </link>
      <link name='Wall_168'>
        <collision name='Wall_168_Collision'>
          <geometry>
            <box>
              <size>5.1 0.15 0.005</size>
            </box>
          </geometry>
          <pose>0 0 0.0025 0 -0 0</pose>
          <max_contacts>10</max_contacts>
          <surface>
            <contact>
              <ode/>
            </contact>
            <bounce/>
            <friction>
              <torsional>
                <ode/>
              </torsional>
              <ode/>
            </friction>
          </surface>
        </collision>
        <visual name='Wall_168_Visual'>
          <pose>0 0 0.0025 0 -0 0</pose>
          <geometry>
            <box>
              <size>5.1 0.15 0.005</size>
            </box>
          </geometry>
          <material>
            <script>
              <uri>file://media/materials/scripts/gazebo.material</uri>
              <name>Gazebo/Grey</name>
            </script>
            <ambient>1 1 1 1</ambient>
          </material>
          <meta>
            <layer>0</layer>
          </meta>
        </visual>
        <pose>-0.64827 -1.73839 0 0 -0 1.57088</pose>
        <self_collide>0</self_collide>
        <enable_wind>0</enable_wind>
        <kinematic>0</kinematic>
      </link>
      <link name='Wall_173'>
        <collision name='Wall_173_Collision'>
          <geometry>
            <box>
              <size>5.1 0.15 0.005</size>
            </box>
          </geometry>
          <pose>0 0 0.0025 0 -0 0</pose>
          <max_contacts>10</max_contacts>
          <surface>
            <contact>
              <ode/>
            </contact>
            <bounce/>
            <friction>
              <torsional>
                <ode/>
              </torsional>
              <ode/>
            </friction>
          </surface>
        </collision>
        <visual name='Wall_173_Visual'>
          <pose>0 0 0.0025 0 -0 0</pose>
          <geometry>
            <box>
              <size>5.1 0.15 0.005</size>
            </box>
          </geometry>
          <material>
            <script>
              <uri>file://media/materials/scripts/gazebo.material</uri>
              <name>Gazebo/Grey</name>
            </script>
            <ambient>1 1 1 1</ambient>
          </material>
          <meta>
            <layer>0</layer>
          </meta>
        </visual>
        <pose>1.52673 -1.73839 0 0 -0 1.57088</pose>
        <self_collide>0</self_collide>
        <enable_wind>0</enable_wind>
        <kinematic>0</kinematic>
      </link>
      <link name='Wall_177'>
        <collision name='Wall_177_Collision'>
          <geometry>
            <box>
              <size>0.6 0.59 3</size>
            </box>
          </geometry>
          <pose>0 0 1.5 0 -0 0</pose>
          <max_contacts>10</max_contacts>
          <surface>
            <contact>
              <ode/>
            </contact>
            <bounce/>
            <friction>
              <torsional>
                <ode/>
              </torsional>
              <ode/>
            </friction>
          </surface>
        </collision>
        <visual name='Wall_177_Visual'>
          <pose>0 0 1.5 0 -0 0</pose>
          <geometry>
            <box>
              <size>0.6 0.59 3</size>
            </box>
          </geometry>
          <material>
            <script>
              <uri>file://media/materials/scripts/gazebo.material</uri>
              <name>Gazebo/Grey</name>
            </script>
            <ambient>0.996078 0.47451 0.0196078 1</ambient>
          </material>
          <meta>
            <layer>0</layer>
          </meta>
        </visual>
        <pose>-3.47407 -3.2865 0 0 -0 0</pose>
        <self_collide>0</self_collide>
        <enable_wind>0</enable_wind>
        <kinematic>0</kinematic>
      </link>
      <link name='Wall_179'>
        <collision name='Wall_179_Collision'>
          <geometry>
            <box>
              <size>0.5 0.15 0.005</size>
            </box>
          </geometry>
          <pose>0 0 0.0025 0 -0 0</pose>
          <max_contacts>10</max_contacts>
          <surface>
            <contact>
              <ode/>
            </contact>
            <bounce/>
            <friction>
              <torsional>
                <ode/>
              </torsional>
              <ode/>
            </friction>
          </surface>
        </collision>
        <visual name='Wall_179_Visual'>
          <pose>0 0 0.0025 0 -0 0</pose>
          <geometry>
            <box>
              <size>0.5 0.15 0.005</size>
            </box>
          </geometry>
          <material>
            <script>
              <uri>file://media/materials/scripts/gazebo.material</uri>
              <name>Gazebo/Grey</name>
            </script>
            <ambient>1 1 1 1</ambient>
          </material>
          <meta>
            <layer>0</layer>
          </meta>
        </visual>
        <pose>-2.64807 -4.2135 0 0 -0 0</pose>
        <self_collide>0</self_collide>
        <enable_wind>0</enable_wind>
        <kinematic>0</kinematic>
      </link>
      <link name='Wall_181'>
        <collision name='Wall_181_Collision'>
          <geometry>
            <box>
              <size>0.5 0.15 0.005</size>
            </box>
          </geometry>
          <pose>0 0 0.0025 0 -0 0</pose>
          <max_contacts>10</max_contacts>
          <surface>
            <contact>
              <ode/>
            </contact>
            <bounce/>
            <friction>
              <torsional>
                <ode/>
              </torsional>
              <ode/>
            </friction>
          </surface>
        </collision>
        <visual name='Wall_181_Visual'>
          <pose>0 0 0.0025 0 -0 0</pose>
          <geometry>
            <box>
              <size>0.5 0.15 0.005</size>
            </box>
          </geometry>
          <material>
            <script>
              <uri>file://media/materials/scripts/gazebo.material</uri>
              <name>Gazebo/Grey</name>
            </script>
            <ambient>1 1 1 1</ambient>
          </material>
          <meta>
            <layer>0</layer>
          </meta>
        </visual>
        <pose>-0.823072 -4.2135 0 0 -0 3.14159</pose>
        <self_collide>0</self_collide>
        <enable_wind>0</enable_wind>
        <kinematic>0</kinematic>
      </link>
      <link name='Wall_183'>
        <collision name='Wall_183_Collision'>
          <geometry>
            <box>
              <size>0.5 0.15 0.005</size>
            </box>
          </geometry>
          <pose>0 0 0.0025 0 -0 0</pose>
          <max_contacts>10</max_contacts>
          <surface>
            <contact>
              <ode/>
            </contact>
            <bounce/>
            <friction>
              <torsional>
                <ode/>
              </torsional>
              <ode/>
            </friction>
          </surface>
        </collision>
        <visual name='Wall_183_Visual'>
          <pose>0 0 0.0025 0 -0 0</pose>
          <geometry>
            <box>
              <size>0.5 0.15 0.005</size>
            </box>
          </geometry>
          <material>
            <script>
              <uri>file://media/materials/scripts/gazebo.material</uri>
              <name>Gazebo/Grey</name>
            </script>
            <ambient>1 1 1 1</ambient>
          </material>
          <meta>
            <layer>0</layer>
          </meta>
        </visual>
        <pose>-0.473072 -4.2135 0 0 -0 0</pose>
        <self_collide>0</self_collide>
        <enable_wind>0</enable_wind>
        <kinematic>0</kinematic>
      </link>
      <link name='Wall_185'>
        <collision name='Wall_185_Collision'>
          <geometry>
            <box>
              <size>0.5 0.15 0.005</size>
            </box>
          </geometry>
          <pose>0 0 0.0025 0 -0 0</pose>
          <max_contacts>10</max_contacts>
          <surface>
            <contact>
              <ode/>
            </contact>
            <bounce/>
            <friction>
              <torsional>
                <ode/>
              </torsional>
              <ode/>
            </friction>
          </surface>
        </collision>
        <visual name='Wall_185_Visual'>
          <pose>0 0 0.0025 0 -0 0</pose>
          <geometry>
            <box>
              <size>0.5 0.15 0.005</size>
            </box>
          </geometry>
          <material>
            <script>
              <uri>file://media/materials/scripts/gazebo.material</uri>
              <name>Gazebo/Grey</name>
            </script>
            <ambient>1 1 1 1</ambient>
          </material>
          <meta>
            <layer>0</layer>
          </meta>
        </visual>
        <pose>1.35193 -4.2135 0 0 -0 3.14159</pose>
        <self_collide>0</self_collide>
        <enable_wind>0</enable_wind>
        <kinematic>0</kinematic>
      </link>
      <link name='Wall_187'>
        <collision name='Wall_187_Collision'>
          <geometry>
            <box>
              <size>0.5 0.15 0.005</size>
            </box>
          </geometry>
          <pose>0 0 0.0025 0 -0 0</pose>
          <max_contacts>10</max_contacts>
          <surface>
            <contact>
              <ode/>
            </contact>
            <bounce/>
            <friction>
              <torsional>
                <ode/>
              </torsional>
              <ode/>
            </friction>
          </surface>
        </collision>
        <visual name='Wall_187_Visual'>
          <pose>0 0 0.0025 0 -0 0</pose>
          <geometry>
            <box>
              <size>0.5 0.15 0.005</size>
            </box>
          </geometry>
          <material>
            <script>
              <uri>file://media/materials/scripts/gazebo.material</uri>
              <name>Gazebo/Grey</name>
            </script>
            <ambient>1 1 1 1</ambient>
          </material>
          <meta>
            <layer>0</layer>
          </meta>
        </visual>
        <pose>1.70193 -4.2135 0 0 -0 0</pose>
        <self_collide>0</self_collide>
        <enable_wind>0</enable_wind>
        <kinematic>0</kinematic>
      </link>
      <link name='Wall_189'>
        <collision name='Wall_189_Collision'>
          <geometry>
            <box>
              <size>0.5 0.15 0.005</size>
            </box>
          </geometry>
          <pose>0 0 0.0025 0 -0 0</pose>
          <max_contacts>10</max_contacts>
          <surface>
            <contact>
              <ode/>
            </contact>
            <bounce/>
            <friction>
              <torsional>
                <ode/>
              </torsional>
              <ode/>
            </friction>
          </surface>
        </collision>
        <visual name='Wall_189_Visual'>
          <pose>0 0 0.0025 0 -0 0</pose>
          <geometry>
            <box>
              <size>0.5 0.15 0.005</size>
            </box>
          </geometry>
          <material>
            <script>
              <uri>file://media/materials/scripts/gazebo.material</uri>
              <name>Gazebo/Grey</name>
            </script>
            <ambient>1 1 1 1</ambient>
          </material>
          <meta>
            <layer>0</layer>
          </meta>
        </visual>
        <pose>3.52893 -4.2055 0 0 -0 3.14159</pose>
        <self_collide>0</self_collide>
        <enable_wind>0</enable_wind>
        <kinematic>0</kinematic>
      </link>
      <static>1</static>
    </model>
    <model name='prius_hybrid'>
      <pose>2.30529 7.23399 0.03 0 -0 0</pose>
      <link name='chassis'>
        <inertial>
          <mass>1326</mass>
          <pose>0 -0.266 0.48 0 -0 0</pose>
          <inertia>
            <ixx>2581.13</ixx>
            <ixy>0</ixy>
            <iyy>591.308</iyy>
            <ixz>0</ixz>
            <iyz>0</iyz>
            <izz>2681.95</izz>
          </inertia>
        </inertial>
        <visual name='chassis_visual'>
          <geometry>
            <mesh>
              <uri>model://prius_hybrid/meshes/Hybrid.obj</uri>
              <scale>0.01 0.01 0.01</scale>
              <submesh>
                <name>Hybrid</name>
                <center>0</center>
              </submesh>
            </mesh>
          </geometry>
        </visual>
        <visual name='interior_visual'>
          <geometry>
            <mesh>
              <uri>model://prius_hybrid/meshes/Hybrid.obj</uri>
              <scale>0.01 0.01 0.01</scale>
              <submesh>
                <name>Hybrid_Interior</name>
                <center>0</center>
              </submesh>
            </mesh>
          </geometry>
        </visual>
        <visual name='windows_visual'>
          <geometry>
            <mesh>
              <uri>model://prius_hybrid/meshes/Hybrid.obj</uri>
              <scale>0.01 0.01 0.01</scale>
              <submesh>
                <name>Hybrid_Windows</name>
                <center>0</center>
              </submesh>
            </mesh>
          </geometry>
        </visual>
        <collision name='chassis'>
          <pose>0 0.05 0.625 0 -0 0</pose>
          <geometry>
            <box>
              <size>1.7526 2.1 0.95</size>
            </box>
          </geometry>
          <max_contacts>10</max_contacts>
          <surface>
            <contact>
              <ode/>
            </contact>
            <bounce/>
            <friction>
              <torsional>
                <ode/>
              </torsional>
              <ode/>
            </friction>
          </surface>
        </collision>
        <collision name='front_bumper'>
          <pose>0 -2 0.458488 0 -0 0</pose>
          <geometry>
            <box>
              <size>1.33728 0.48 0.566691</size>
            </box>
          </geometry>
          <max_contacts>10</max_contacts>
          <surface>
            <contact>
              <ode/>
            </contact>
            <bounce/>
            <friction>
              <torsional>
                <ode/>
              </torsional>
              <ode/>
            </friction>
          </surface>
        </collision>
        <collision name='hood'>
          <pose>0 -1.90084 0.676305 0.341247 -0 0</pose>
          <geometry>
            <box>
              <size>1.59797 0.493107 0.265468</size>
            </box>
          </geometry>
          <max_contacts>10</max_contacts>
          <surface>
            <contact>
              <ode/>
            </contact>
            <bounce/>
            <friction>
              <torsional>
                <ode/>
              </torsional>
              <ode/>
            </friction>
          </surface>
        </collision>
        <collision name='windshield'>
          <pose>0 -0.875105 1.03227 0.335476 -0 0</pose>
          <geometry>
            <box>
              <size>1.16838 1.65425 0.272347</size>
            </box>
          </geometry>
          <max_contacts>10</max_contacts>
          <surface>
            <contact>
              <ode/>
            </contact>
            <bounce/>
            <friction>
              <torsional>
                <ode/>
              </torsional>
              <ode/>
            </friction>
          </surface>
        </collision>
        <collision name='top_front'>
          <pose>0 0.161236 1.38604 0.13503 -0 0</pose>
          <geometry>
            <box>
              <size>1.27915 0.625988 0.171868</size>
            </box>
          </geometry>
          <max_contacts>10</max_contacts>
          <surface>
            <contact>
              <ode/>
            </contact>
            <bounce/>
            <friction>
              <torsional>
                <ode/>
              </torsional>
              <ode/>
            </friction>
          </surface>
        </collision>
        <collision name='top_rear'>
          <pose>0 0.817696 1.36007 -0.068997 0 0</pose>
          <geometry>
            <box>
              <size>1.28513 0.771189 0.226557</size>
            </box>
          </geometry>
          <max_contacts>10</max_contacts>
          <surface>
            <contact>
              <ode/>
            </contact>
            <bounce/>
            <friction>
              <torsional>
                <ode/>
              </torsional>
              <ode/>
            </friction>
          </surface>
        </collision>
        <collision name='rear_window'>
          <pose>0 1.64053 1.17513 -0.262017 0 0</pose>
          <geometry>
            <box>
              <size>1.26785 1.11634 0.244286</size>
            </box>
          </geometry>
          <max_contacts>10</max_contacts>
          <surface>
            <contact>
              <ode/>
            </contact>
            <bounce/>
            <friction>
              <torsional>
                <ode/>
              </torsional>
              <ode/>
            </friction>
          </surface>
        </collision>
        <collision name='trunk'>
          <pose>0 1.63706 0.88818 0 -0 0</pose>
          <geometry>
            <box>
              <size>1.78806 1.13899 0.482746</size>
            </box>
          </geometry>
          <max_contacts>10</max_contacts>
          <surface>
            <contact>
              <ode/>
            </contact>
            <bounce/>
            <friction>
              <torsional>
                <ode/>
              </torsional>
              <ode/>
            </friction>
          </surface>
        </collision>
        <collision name='back_bumper'>
          <pose>0 2.05445 0.57787 0 -0 0</pose>
          <geometry>
            <box>
              <size>1.78165 0.512093 0.581427</size>
            </box>
          </geometry>
          <max_contacts>10</max_contacts>
          <surface>
            <contact>
              <ode/>
            </contact>
            <bounce/>
            <friction>
              <torsional>
                <ode/>
              </torsional>
              <ode/>
            </friction>
          </surface>
        </collision>
        <self_collide>0</self_collide>
        <enable_wind>0</enable_wind>
        <kinematic>0</kinematic>
      </link>
      <link name='steering_wheel'>
        <pose>0.357734 -0.627868 0.988243 -1.3021 0 0</pose>
        <inertial>
          <mass>1</mass>
          <inertia>
            <ixx>0.145833</ixx>
            <ixy>0</ixy>
            <ixz>0</ixz>
            <iyy>0.145833</iyy>
            <iyz>0</iyz>
            <izz>0.125</izz>
          </inertia>
          <pose>0 0 0 0 -0 0</pose>
        </inertial>
        <collision name='collision'>
          <geometry>
            <cylinder>
              <radius>0.178172</radius>
              <length>0.041845</length>
            </cylinder>
          </geometry>
          <surface>
            <contact>
              <ode>
                <min_depth>0.003</min_depth>
              </ode>
            </contact>
            <bounce/>
            <friction>
              <torsional>
                <ode/>
              </torsional>
              <ode/>
            </friction>
          </surface>
          <max_contacts>10</max_contacts>
        </collision>
        <visual name='visual'>
          <pose>0 0 0 1.3021 -0 0</pose>
          <geometry>
            <mesh>
              <uri>model://prius_hybrid/meshes/Hybrid.obj</uri>
              <scale>0.01 0.01 0.01</scale>
              <submesh>
                <name>Steering_Wheel</name>
                <center>1</center>
              </submesh>
            </mesh>
          </geometry>
        </visual>
        <self_collide>0</self_collide>
        <enable_wind>0</enable_wind>
        <kinematic>0</kinematic>
      </link>
      <link name='front_left_wheel'>
        <pose>0.76 -1.41 0.3 0 -0 0</pose>
        <inertial>
          <mass>11</mass>
          <inertia>
            <ixx>0.586312</ixx>
            <ixy>0</ixy>
            <iyy>0.335529</iyy>
            <ixz>0</ixz>
            <iyz>0</iyz>
            <izz>0.335529</izz>
          </inertia>
          <pose>0 0 0 0 -0 0</pose>
        </inertial>
        <visual name='visual'>
          <pose>0.04 0 0 0 -0 0</pose>
          <geometry>
            <mesh>
              <uri>model://prius_hybrid/meshes/Hybrid.obj</uri>
              <scale>0.01 0.01 0.01</scale>
              <submesh>
                <name>Wheel_Front_Left_</name>
                <center>1</center>
              </submesh>
            </mesh>
          </geometry>
        </visual>
        <collision name='collision'>
          <pose>0 0 0 3.14159 1.57079 3.14159</pose>
          <geometry>
            <sphere>
              <radius>0.31265</radius>
            </sphere>
          </geometry>
          <surface>
            <friction>
              <ode>
                <mu>0.9</mu>
                <mu2>0.9</mu2>
                <slip1>0</slip1>
                <slip2>0</slip2>
              </ode>
              <torsional>
                <ode/>
              </torsional>
            </friction>
            <contact>
              <ode>
                <min_depth>0.001</min_depth>
                <kp>1e+09</kp>
              </ode>
            </contact>
            <bounce/>
          </surface>
          <max_contacts>10</max_contacts>
        </collision>
        <self_collide>0</self_collide>
        <enable_wind>0</enable_wind>
        <kinematic>0</kinematic>
      </link>
      <link name='front_right_wheel'>
        <pose>-0.76 -1.41 0.3 0 -0 0</pose>
        <inertial>
          <mass>11</mass>
          <inertia>
            <ixx>0.586312</ixx>
            <ixy>0</ixy>
            <iyy>0.335529</iyy>
            <ixz>0</ixz>
            <iyz>0</iyz>
            <izz>0.335529</izz>
          </inertia>
          <pose>0 0 0 0 -0 0</pose>
        </inertial>
        <visual name='visual'>
          <pose>-0.04 0 0 0 -0 0</pose>
          <pose>0 0 0 0 -0 0</pose>
          <geometry>
            <mesh>
              <uri>model://prius_hybrid/meshes/Hybrid.obj</uri>
              <scale>0.01 0.01 0.01</scale>
              <submesh>
                <name>Wheel_Front_Right</name>
                <center>1</center>
              </submesh>
            </mesh>
          </geometry>
        </visual>
        <collision name='collision'>
          <pose>0 0 0 3.14159 1.57079 3.14159</pose>
          <geometry>
            <sphere>
              <radius>0.31265</radius>
            </sphere>
          </geometry>
          <surface>
            <friction>
              <ode>
                <mu>0.9</mu>
                <mu2>0.9</mu2>
                <slip1>0</slip1>
                <slip2>0</slip2>
              </ode>
              <torsional>
                <ode/>
              </torsional>
            </friction>
            <contact>
              <ode>
                <min_depth>0.001</min_depth>
                <kp>1e+09</kp>
              </ode>
            </contact>
            <bounce/>
          </surface>
          <max_contacts>10</max_contacts>
        </collision>
        <self_collide>0</self_collide>
        <enable_wind>0</enable_wind>
        <kinematic>0</kinematic>
      </link>
      <link name='rear_left_wheel'>
        <pose>0.786 1.45 0.3 0 -0 0</pose>
        <inertial>
          <mass>11</mass>
          <inertia>
            <ixx>0.586312</ixx>
            <ixy>0</ixy>
            <iyy>0.335529</iyy>
            <ixz>0</ixz>
            <iyz>0</iyz>
            <izz>0.335529</izz>
          </inertia>
          <pose>0 0 0 0 -0 0</pose>
        </inertial>
        <visual name='visual'>
          <pose>0.04 0 0 0 -0 0</pose>
          <geometry>
            <mesh>
              <uri>model://prius_hybrid/meshes/Hybrid.obj</uri>
              <scale>0.01 0.01 0.01</scale>
              <submesh>
                <name>Wheel_Front_Left_</name>
                <center>1</center>
              </submesh>
            </mesh>
          </geometry>
        </visual>
        <collision name='collision'>
          <pose>0 0 0 3.14159 1.57079 3.14159</pose>
          <geometry>
            <sphere>
              <radius>0.31265</radius>
            </sphere>
          </geometry>
          <surface>
            <friction>
              <ode>
                <mu>1.1</mu>
                <mu2>1.1</mu2>
                <slip1>0</slip1>
                <slip2>0</slip2>
              </ode>
              <torsional>
                <ode/>
              </torsional>
            </friction>
            <contact>
              <ode>
                <min_depth>0.001</min_depth>
                <kp>1e+09</kp>
              </ode>
            </contact>
            <bounce/>
          </surface>
          <max_contacts>10</max_contacts>
        </collision>
        <self_collide>0</self_collide>
        <enable_wind>0</enable_wind>
        <kinematic>0</kinematic>
      </link>
      <link name='rear_right_wheel'>
        <pose>-0.786 1.45 0.3 0 -0 0</pose>
        <inertial>
          <mass>11</mass>
          <inertia>
            <ixx>0.586312</ixx>
            <ixy>0</ixy>
            <iyy>0.335529</iyy>
            <ixz>0</ixz>
            <iyz>0</iyz>
            <izz>0.335529</izz>
          </inertia>
          <pose>0 0 0 0 -0 0</pose>
        </inertial>
        <visual name='visual'>
          <pose>-0.04 0 0 0 -0 0</pose>
          <geometry>
            <mesh>
              <uri>model://prius_hybrid/meshes/Hybrid.obj</uri>
              <scale>0.01 0.01 0.01</scale>
              <submesh>
                <name>Wheel_Front_Right</name>
                <center>1</center>
              </submesh>
            </mesh>
          </geometry>
        </visual>
        <collision name='collision'>
          <pose>0 0 0 3.14159 1.57079 3.14159</pose>
          <geometry>
            <sphere>
              <radius>0.31265</radius>
            </sphere>
          </geometry>
          <surface>
            <friction>
              <ode>
                <mu>1.1</mu>
                <mu2>1.1</mu2>
                <slip1>0</slip1>
                <slip2>0</slip2>
              </ode>
              <torsional>
                <ode/>
              </torsional>
            </friction>
            <contact>
              <ode>
                <min_depth>0.001</min_depth>
                <kp>1e+09</kp>
              </ode>
            </contact>
            <bounce/>
          </surface>
          <max_contacts>10</max_contacts>
        </collision>
        <self_collide>0</self_collide>
        <enable_wind>0</enable_wind>
        <kinematic>0</kinematic>
      </link>
      <joint name='front_left_combined_joint' type='universal'>
        <pose>0 0 0 -0.087266 0 0</pose>
        <child>front_left_wheel</child>
        <parent>chassis</parent>
        <axis>
          <xyz>0 0 1</xyz>
          <limit>
            <lower>-0.8727</lower>
            <upper>0.8727</upper>
          </limit>
          <dynamics>
            <spring_reference>0</spring_reference>
            <spring_stiffness>0</spring_stiffness>
          </dynamics>
        </axis>
        <axis2>
          <xyz>1 0 0</xyz>
          <dynamics>
            <friction>18.0474</friction>
            <spring_reference>0</spring_reference>
            <spring_stiffness>0</spring_stiffness>
          </dynamics>
          <limit>
            <upper>1e+16</upper>
            <lower>-1e+16</lower>
          </limit>
        </axis2>
      </joint>
      <joint name='front_right_combined_joint' type='universal'>
        <pose>0 0 0 -0.087266 0 0</pose>
        <child>front_right_wheel</child>
        <parent>chassis</parent>
        <axis>
          <xyz>0 0 1</xyz>
          <limit>
            <lower>-0.8727</lower>
            <upper>0.8727</upper>
          </limit>
          <dynamics>
            <spring_reference>0</spring_reference>
            <spring_stiffness>0</spring_stiffness>
          </dynamics>
        </axis>
        <axis2>
          <xyz>1 0 0</xyz>
          <dynamics>
            <friction>18.0474</friction>
            <spring_reference>0</spring_reference>
            <spring_stiffness>0</spring_stiffness>
          </dynamics>
          <limit>
            <upper>1e+16</upper>
            <lower>-1e+16</lower>
          </limit>
        </axis2>
      </joint>
      <link name='rear_axle'>
        <pose>0 1.45 0.3 0 -0 0</pose>
        <inertial>
          <mass>30</mass>
          <inertia>
            <ixx>0.084375</ixx>
            <ixy>0</ixy>
            <iyy>4.64581</iyy>
            <ixz>0</ixz>
            <iyz>0</iyz>
            <izz>4.64581</izz>
          </inertia>
          <pose>0 0 0 0 -0 0</pose>
        </inertial>
        <visual name='visual'>
          <pose>0 0 0 3.14159 1.57079 3.14159</pose>
          <geometry>
            <cylinder>
              <length>1.357</length>
              <radius>0.075</radius>
            </cylinder>
          </geometry>
          <material>
            <script>
              <name>Gazebo/Grey</name>
              <uri>file://media/materials/scripts/gazebo.material</uri>
            </script>
          </material>
        </visual>
        <self_collide>0</self_collide>
        <enable_wind>0</enable_wind>
        <kinematic>0</kinematic>
      </link>
      <joint name='rear_axle_joint' type='revolute'>
        <child>rear_axle</child>
        <parent>chassis</parent>
        <axis>
          <xyz>0 1 0</xyz>
          <limit>
            <lower>-0.0508906</lower>
            <upper>0.0508906</upper>
          </limit>
          <dynamics>
            <spring_stiffness>20000</spring_stiffness>
            <damping>2000</damping>
            <spring_reference>0</spring_reference>
          </dynamics>
        </axis>
      </joint>
      <joint name='rear_left_wheel_joint' type='revolute'>
        <child>rear_left_wheel</child>
        <parent>rear_axle</parent>
        <axis>
          <xyz>1 0 0</xyz>
          <dynamics>
            <friction>12.0316</friction>
            <spring_reference>0</spring_reference>
            <spring_stiffness>0</spring_stiffness>
          </dynamics>
          <limit>
            <lower>-1e+16</lower>
            <upper>1e+16</upper>
          </limit>
        </axis>
      </joint>
      <joint name='rear_right_wheel_joint' type='revolute'>
        <child>rear_right_wheel</child>
        <parent>rear_axle</parent>
        <axis>
          <xyz>1 0 0</xyz>
          <dynamics>
            <friction>12.0316</friction>
            <spring_reference>0</spring_reference>
            <spring_stiffness>0</spring_stiffness>
          </dynamics>
          <limit>
            <lower>-1e+16</lower>
            <upper>1e+16</upper>
          </limit>
        </axis>
      </joint>
      <joint name='steering_joint' type='revolute'>
        <pose>-0.002 0 0 0 -0 0</pose>
        <parent>chassis</parent>
        <child>steering_wheel</child>
        <axis>
          <xyz expressed_in='__model__'>0 0.964095 0.265556</xyz>
          <limit>
            <lower>-7.85</lower>
            <upper>7.85</upper>
          </limit>
          <dynamics>
            <damping>1</damping>
            <spring_reference>0</spring_reference>
            <spring_stiffness>0</spring_stiffness>
          </dynamics>
        </axis>
        <physics>
          <ode>
            <cfm_damping>1</cfm_damping>
            <limit>
              <cfm>0</cfm>
              <erp>0.2</erp>
            </limit>
          </ode>
        </physics>
      </joint>
    </model>
    <model name='hatchback_red'>
      <static>1</static>
      <link name='link'>
        <collision name='collision'>
          <pose>0 0 0 0 -0 1.5708</pose>
          <geometry>
            <mesh>
              <scale>0.0254 0.0254 0.0254</scale>
              <uri>model://hatchback_red/meshes/hatchback.obj</uri>
            </mesh>
          </geometry>
          <max_contacts>10</max_contacts>
          <surface>
            <contact>
              <ode/>
            </contact>
            <bounce/>
            <friction>
              <torsional>
                <ode/>
              </torsional>
              <ode/>
            </friction>
          </surface>
        </collision>
        <visual name='visual'>
          <pose>0 0 0 0 -0 1.5708</pose>
          <geometry>
            <mesh>
              <scale>0.0254 0.0254 0.0254</scale>
              <uri>model://hatchback_red/meshes/hatchback.obj</uri>
            </mesh>
          </geometry>
        </visual>
        <self_collide>0</self_collide>
        <enable_wind>0</enable_wind>
        <kinematic>0</kinematic>
      </link>
      <pose>-10.0959 0.28546 0 0 -0 0</pose>
    </model>
    <model name='suv'>
      <static>1</static>
      <link name='link'>
        <collision name='collision'>
          <pose>0 0 0 0 0 -1.5708</pose>
          <geometry>
            <mesh>
              <scale>0.06 0.06 0.06</scale>
              <uri>model://suv/meshes/suv.obj</uri>
            </mesh>
          </geometry>
          <max_contacts>10</max_contacts>
          <surface>
            <contact>
              <ode/>
            </contact>
            <bounce/>
            <friction>
              <torsional>
                <ode/>
              </torsional>
              <ode/>
            </friction>
          </surface>
        </collision>
        <visual name='visual'>
          <pose>0 0 0 0 0 -1.5708</pose>
          <geometry>
            <mesh>
              <scale>0.06 0.06 0.06</scale>
              <uri>model://suv/meshes/suv.obj</uri>
            </mesh>
          </geometry>
        </visual>
        <self_collide>0</self_collide>
        <enable_wind>0</enable_wind>
        <kinematic>0</kinematic>
      </link>
      <pose>7.60116 7.65468 0 0 -0 0</pose>
    </model>
    <model name='wall_L'>
      <pose>-5.55088 0.586859 0 0 -0 0</pose>
      <link name='Wall_12'>
        <collision name='Wall_12_Collision'>
          <geometry>
            <box>
              <size>9.75 0.15 2.5</size>
            </box>
          </geometry>
          <pose>0 0 1.25 0 -0 0</pose>
          <max_contacts>10</max_contacts>
          <surface>
            <contact>
              <ode/>
            </contact>
            <bounce/>
            <friction>
              <torsional>
                <ode/>
              </torsional>
              <ode/>
            </friction>
          </surface>
        </collision>
        <visual name='Wall_12_Visual'>
          <pose>0 0 1.25 0 -0 0</pose>
          <geometry>
            <box>
              <size>9.75 0.15 2.5</size>
            </box>
          </geometry>
          <material>
            <script>
              <uri>file://media/materials/scripts/gazebo.material</uri>
              <name>Gazebo/Grey</name>
            </script>
            <ambient>1 1 1 1</ambient>
          </material>
          <meta>
            <layer>0</layer>
          </meta>
        </visual>
        <pose>-0.675878 -7.575 0 0 -0 3.14159</pose>
        <self_collide>0</self_collide>
        <enable_wind>0</enable_wind>
        <kinematic>0</kinematic>
      </link>
      <link name='Wall_14'>
        <collision name='Wall_14_Collision'>
          <geometry>
            <box>
              <size>15.25 0.15 2.5</size>
            </box>
          </geometry>
          <pose>0 0 1.25 0 -0 0</pose>
          <max_contacts>10</max_contacts>
          <surface>
            <contact>
              <ode/>
            </contact>
            <bounce/>
            <friction>
              <torsional>
                <ode/>
              </torsional>
              <ode/>
            </friction>
          </surface>
        </collision>
        <visual name='Wall_14_Visual'>
          <pose>0 0 1.25 0 -0 0</pose>
          <geometry>
            <box>
              <size>15.25 0.15 2.5</size>
            </box>
          </geometry>
          <material>
            <script>
              <uri>file://media/materials/scripts/gazebo.material</uri>
              <name>Gazebo/Grey</name>
            </script>
            <ambient>1 1 1 1</ambient>
          </material>
          <meta>
            <layer>0</layer>
          </meta>
        </visual>
        <pose>-5.47588 0.025 0 0 -0 -1.5708</pose>
        <self_collide>0</self_collide>
        <enable_wind>0</enable_wind>
        <kinematic>0</kinematic>
      </link>
      <link name='Wall_16'>
        <collision name='Wall_16_Collision'>
          <geometry>
            <box>
              <size>5.75 0.15 2.5</size>
            </box>
          </geometry>
          <pose>0 0 1.25 0 -0 0</pose>
          <max_contacts>10</max_contacts>
          <surface>
            <contact>
              <ode/>
            </contact>
            <bounce/>
            <friction>
              <torsional>
                <ode/>
              </torsional>
              <ode/>
            </friction>
          </surface>
        </collision>
        <visual name='Wall_16_Visual'>
          <pose>0 0 1.25 0 -0 0</pose>
          <geometry>
            <box>
              <size>5.75 0.15 2.5</size>
            </box>
          </geometry>
          <material>
            <script>
              <uri>file://media/materials/scripts/gazebo.material</uri>
              <name>Gazebo/Grey</name>
            </script>
            <ambient>1 1 1 1</ambient>
          </material>
          <meta>
            <layer>0</layer>
          </meta>
        </visual>
        <pose>4.12412 -4.775 0 0 -0 1.5708</pose>
        <self_collide>0</self_collide>
        <enable_wind>0</enable_wind>
        <kinematic>0</kinematic>
      </link>
      <link name='Wall_18'>
        <collision name='Wall_18_Collision'>
          <geometry>
            <box>
              <size>5.25 0.15 2.5</size>
            </box>
          </geometry>
          <pose>0 0 1.25 0 -0 0</pose>
          <max_contacts>10</max_contacts>
          <surface>
            <contact>
              <ode/>
            </contact>
            <bounce/>
            <friction>
              <torsional>
                <ode/>
              </torsional>
              <ode/>
            </friction>
          </surface>
        </collision>
        <visual name='Wall_18_Visual'>
          <pose>0 0 1.25 0 -0 0</pose>
          <geometry>
            <box>
              <size>5.25 0.15 2.5</size>
            </box>
          </geometry>
          <material>
            <script>
              <uri>file://media/materials/scripts/gazebo.material</uri>
              <name>Gazebo/Grey</name>
            </script>
            <ambient>1 1 1 1</ambient>
          </material>
          <meta>
            <layer>0</layer>
          </meta>
        </visual>
        <pose>4.12412 5.025 0 0 -0 -1.5708</pose>
        <self_collide>0</self_collide>
        <enable_wind>0</enable_wind>
        <kinematic>0</kinematic>
      </link>
      <link name='Wall_7'>
        <collision name='Wall_7_Collision'>
          <geometry>
            <box>
              <size>9.75 0.15 2.5</size>
            </box>
          </geometry>
          <pose>0 0 1.25 0 -0 0</pose>
          <max_contacts>10</max_contacts>
          <surface>
            <contact>
              <ode/>
            </contact>
            <bounce/>
            <friction>
              <torsional>
                <ode/>
              </torsional>
              <ode/>
            </friction>
          </surface>
        </collision>
        <visual name='Wall_7_Visual'>
          <pose>0 0 1.25 0 -0 0</pose>
          <geometry>
            <box>
              <size>9.75 0.15 2.5</size>
            </box>
          </geometry>
          <material>
            <script>
              <uri>file://media/materials/scripts/gazebo.material</uri>
              <name>Gazebo/Grey</name>
            </script>
            <ambient>1 1 1 1</ambient>
          </material>
          <meta>
            <layer>0</layer>
          </meta>
        </visual>
        <pose>-0.675878 7.575 0 0 -0 0</pose>
        <self_collide>0</self_collide>
        <enable_wind>0</enable_wind>
        <kinematic>0</kinematic>
      </link>
      <static>1</static>
    </model>
    <model name='tb1'>
      <pose>-1.5 -0.5 0.01 0 -0 0</pose>
      <link name='base_footprint'>
        <self_collide>0</self_collide>
        <inertial>
          <pose>0 0 0 0 -0 0</pose>
          <inertia>
            <ixx>1</ixx>
            <ixy>0</ixy>
            <ixz>0</ixz>
            <iyy>1</iyy>
            <iyz>0</iyz>
            <izz>1</izz>
          </inertia>
          <mass>1</mass>
        </inertial>
        <enable_wind>0</enable_wind>
        <kinematic>0</kinematic>
      </link>
      <link name='base_link'>
        <inertial>
          <pose>-0.064 0 0.048 0 -0 0</pose>
          <inertia>
            <ixx>0.0421114</ixx>
            <ixy>0</ixy>
            <ixz>0</ixz>
            <iyy>0.0421114</iyy>
            <iyz>0</iyz>
            <izz>0.0752549</izz>
          </inertia>
          <mass>1.37291</mass>
        </inertial>
        <collision name='base_collision'>
          <pose>-0.064 0 0.048 0 -0 0</pose>
          <geometry>
            <box>
              <size>0.265 0.265 0.089</size>
            </box>
          </geometry>
          <max_contacts>10</max_contacts>
          <surface>
            <contact>
              <ode/>
            </contact>
            <bounce/>
            <friction>
              <torsional>
                <ode/>
              </torsional>
              <ode/>
            </friction>
          </surface>
        </collision>
        <visual name='base_visual'>
          <pose>-0.064 0 0 0 -0 0</pose>
          <geometry>
            <mesh>
              <uri>model://turtlebot3_common/meshes/waffle_base.dae</uri>
              <scale>0.001 0.001 0.001</scale>
            </mesh>
          </geometry>
        </visual>
        <self_collide>0</self_collide>
        <enable_wind>0</enable_wind>
        <kinematic>0</kinematic>
      </link>
      <link name='imu_link'>
        <sensor name='tb3_imu' type='imu'>
          <always_on>1</always_on>
          <update_rate>200</update_rate>
          <imu>
            <angular_velocity>
              <x>
                <noise type='gaussian'>
                  <mean>0</mean>
                  <stddev>0.0002</stddev>
                </noise>
              </x>
              <y>
                <noise type='gaussian'>
                  <mean>0</mean>
                  <stddev>0.0002</stddev>
                </noise>
              </y>
              <z>
                <noise type='gaussian'>
                  <mean>0</mean>
                  <stddev>0.0002</stddev>
                </noise>
              </z>
            </angular_velocity>
            <linear_acceleration>
              <x>
                <noise type='gaussian'>
                  <mean>0</mean>
                  <stddev>0.017</stddev>
                </noise>
              </x>
              <y>
                <noise type='gaussian'>
                  <mean>0</mean>
                  <stddev>0.017</stddev>
                </noise>
              </y>
              <z>
                <noise type='gaussian'>
                  <mean>0</mean>
                  <stddev>0.017</stddev>
                </noise>
              </z>
            </linear_acceleration>
            <angular_velocity/>
            <linear_acceleration/>
          </imu>
          <plugin name='turtlebot3_imu' filename='libgazebo_ros_imu_sensor.so'>
            <ros>
              <remapping>~/out:=imu</remapping>
              <namespace>/tb1</namespace>
            </ros>
          </plugin>
        </sensor>
        <self_collide>0</self_collide>
        <inertial>
          <pose>0 0 0 0 -0 0</pose>
          <inertia>
            <ixx>1</ixx>
            <ixy>0</ixy>
            <ixz>0</ixz>
            <iyy>1</iyy>
            <iyz>0</iyz>
            <izz>1</izz>
          </inertia>
          <mass>1</mass>
        </inertial>
        <enable_wind>0</enable_wind>
        <kinematic>0</kinematic>
      </link>
      <link name='base_scan'>
        <inertial>
          <pose>-0.052 0 0.111 0 -0 0</pose>
          <inertia>
            <ixx>0.001</ixx>
            <ixy>0</ixy>
            <ixz>0</ixz>
            <iyy>0.001</iyy>
            <iyz>0</iyz>
            <izz>0.001</izz>
          </inertia>
          <mass>0.114</mass>
        </inertial>
        <collision name='lidar_sensor_collision'>
          <pose>-0.052 0 0.111 0 -0 0</pose>
          <geometry>
            <cylinder>
              <radius>0.0508</radius>
              <length>0.055</length>
            </cylinder>
          </geometry>
          <max_contacts>10</max_contacts>
          <surface>
            <contact>
              <ode/>
            </contact>
            <bounce/>
            <friction>
              <torsional>
                <ode/>
              </torsional>
              <ode/>
            </friction>
          </surface>
        </collision>
        <visual name='lidar_sensor_visual'>
          <pose>-0.064 0 0.121 0 -0 0</pose>
          <geometry>
            <mesh>
              <uri>model://turtlebot3_common/meshes/lds.dae</uri>
              <scale>0.001 0.001 0.001</scale>
            </mesh>
          </geometry>
        </visual>
        <sensor name='hls_lfcd_lds' type='ray'>
          <always_on>1</always_on>
          <visualize>0</visualize>
          <pose>-0.064 0 0.121 0 -0 0</pose>
          <update_rate>5</update_rate>
          <ray>
            <scan>
              <horizontal>
                <samples>360</samples>
                <resolution>1</resolution>
                <min_angle>0</min_angle>
                <max_angle>6.28</max_angle>
              </horizontal>
              <vertical>
                <samples>1</samples>
                <min_angle>0</min_angle>
                <max_angle>0</max_angle>
              </vertical>
            </scan>
            <range>
              <min>0.12</min>
              <max>3.5</max>
              <resolution>0.015</resolution>
            </range>
            <noise>
              <type>gaussian</type>
              <mean>0</mean>
              <stddev>0.01</stddev>
            </noise>
          </ray>
          <plugin name='turtlebot3_laserscan' filename='libgazebo_ros_ray_sensor.so'>
            <ros>
              <remapping>~/out:=scan</remapping>
              <namespace>/tb1</namespace>
            </ros>
            <output_type>sensor_msgs/LaserScan</output_type>
            <frame_name>base_scan</frame_name>
          </plugin>
        </sensor>
        <self_collide>0</self_collide>
        <enable_wind>0</enable_wind>
        <kinematic>0</kinematic>
      </link>
      <link name='wheel_left_link'>
        <inertial>
          <pose>0 0.144 0.023 -1.57 0 0</pose>
          <inertia>
            <ixx>1.11756e-05</ixx>
            <ixy>-4.23698e-11</ixy>
            <ixz>-5.93817e-09</ixz>
            <iyy>1.11924e-05</iyy>
            <iyz>-1.44001e-11</iyz>
            <izz>2.07126e-05</izz>
          </inertia>
          <mass>0.1</mass>
        </inertial>
        <collision name='wheel_left_collision'>
          <pose>0 0.144 0.023 -1.57 0 0</pose>
          <geometry>
            <cylinder>
              <radius>0.033</radius>
              <length>0.018</length>
            </cylinder>
          </geometry>
          <surface>
            <friction>
              <ode>
                <mu>100000</mu>
                <mu2>100000</mu2>
                <fdir1>0 0 0</fdir1>
                <slip1>0</slip1>
                <slip2>0</slip2>
              </ode>
              <torsional>
                <ode/>
              </torsional>
            </friction>
            <contact>
              <ode>
                <soft_cfm>0</soft_cfm>
                <soft_erp>0.2</soft_erp>
                <kp>100000</kp>
                <kd>1</kd>
                <max_vel>0.01</max_vel>
                <min_depth>0.001</min_depth>
              </ode>
            </contact>
            <bounce/>
          </surface>
          <max_contacts>10</max_contacts>
        </collision>
        <visual name='wheel_left_visual'>
          <pose>0 0.144 0.023 0 -0 0</pose>
          <geometry>
            <mesh>
              <uri>model://turtlebot3_common/meshes/tire.dae</uri>
              <scale>0.001 0.001 0.001</scale>
            </mesh>
          </geometry>
        </visual>
        <self_collide>0</self_collide>
        <enable_wind>0</enable_wind>
        <kinematic>0</kinematic>
      </link>
      <link name='wheel_right_link'>
        <inertial>
          <pose>0 -0.144 0.023 -1.57 0 0</pose>
          <inertia>
            <ixx>1.11756e-05</ixx>
            <ixy>-4.23698e-11</ixy>
            <ixz>-5.93817e-09</ixz>
            <iyy>1.11924e-05</iyy>
            <iyz>-1.44001e-11</iyz>
            <izz>2.07126e-05</izz>
          </inertia>
          <mass>0.1</mass>
        </inertial>
        <collision name='wheel_right_collision'>
          <pose>0 -0.144 0.023 -1.57 0 0</pose>
          <geometry>
            <cylinder>
              <radius>0.033</radius>
              <length>0.018</length>
            </cylinder>
          </geometry>
          <surface>
            <friction>
              <ode>
                <mu>100000</mu>
                <mu2>100000</mu2>
                <fdir1>0 0 0</fdir1>
                <slip1>0</slip1>
                <slip2>0</slip2>
              </ode>
              <torsional>
                <ode/>
              </torsional>
            </friction>
            <contact>
              <ode>
                <soft_cfm>0</soft_cfm>
                <soft_erp>0.2</soft_erp>
                <kp>100000</kp>
                <kd>1</kd>
                <max_vel>0.01</max_vel>
                <min_depth>0.001</min_depth>
              </ode>
            </contact>
            <bounce/>
          </surface>
          <max_contacts>10</max_contacts>
        </collision>
        <visual name='wheel_right_visual'>
          <pose>0 -0.144 0.023 0 -0 0</pose>
          <geometry>
            <mesh>
              <uri>model://turtlebot3_common/meshes/tire.dae</uri>
              <scale>0.001 0.001 0.001</scale>
            </mesh>
          </geometry>
        </visual>
        <self_collide>0</self_collide>
        <enable_wind>0</enable_wind>
        <kinematic>0</kinematic>
      </link>
      <link name='caster_back_right_link'>
        <pose>-0.177 -0.064 -0.004 -1.57 0 0</pose>
        <inertial>
          <mass>0.001</mass>
          <inertia>
            <ixx>1e-05</ixx>
            <ixy>0</ixy>
            <ixz>0</ixz>
            <iyy>1e-05</iyy>
            <iyz>0</iyz>
            <izz>1e-05</izz>
          </inertia>
          <pose>0 0 0 0 -0 0</pose>
        </inertial>
        <collision name='collision'>
          <geometry>
            <sphere>
              <radius>0.005</radius>
            </sphere>
          </geometry>
          <surface>
            <contact>
              <ode>
                <soft_cfm>0</soft_cfm>
                <soft_erp>0.2</soft_erp>
                <kp>100000</kp>
                <kd>1</kd>
                <max_vel>0.01</max_vel>
                <min_depth>0.001</min_depth>
              </ode>
            </contact>
            <bounce/>
            <friction>
              <torsional>
                <ode/>
              </torsional>
              <ode/>
            </friction>
          </surface>
          <max_contacts>10</max_contacts>
        </collision>
        <self_collide>0</self_collide>
        <enable_wind>0</enable_wind>
        <kinematic>0</kinematic>
      </link>
      <link name='caster_back_left_link'>
        <pose>-0.177 0.064 -0.004 -1.57 0 0</pose>
        <inertial>
          <mass>0.001</mass>
          <inertia>
            <ixx>1e-05</ixx>
            <ixy>0</ixy>
            <ixz>0</ixz>
            <iyy>1e-05</iyy>
            <iyz>0</iyz>
            <izz>1e-05</izz>
          </inertia>
          <pose>0 0 0 0 -0 0</pose>
        </inertial>
        <collision name='collision'>
          <geometry>
            <sphere>
              <radius>0.005</radius>
            </sphere>
          </geometry>
          <surface>
            <contact>
              <ode>
                <soft_cfm>0</soft_cfm>
                <soft_erp>0.2</soft_erp>
                <kp>100000</kp>
                <kd>1</kd>
                <max_vel>0.01</max_vel>
                <min_depth>0.001</min_depth>
              </ode>
            </contact>
            <bounce/>
            <friction>
              <torsional>
                <ode/>
              </torsional>
              <ode/>
            </friction>
          </surface>
          <max_contacts>10</max_contacts>
        </collision>
        <self_collide>0</self_collide>
        <enable_wind>0</enable_wind>
        <kinematic>0</kinematic>
      </link>
      <link name='camera_link'>
        <self_collide>0</self_collide>
        <inertial>
          <pose>0 0 0 0 -0 0</pose>
          <inertia>
            <ixx>1</ixx>
            <ixy>0</ixy>
            <ixz>0</ixz>
            <iyy>1</iyy>
            <iyz>0</iyz>
            <izz>1</izz>
          </inertia>
          <mass>1</mass>
        </inertial>
        <enable_wind>0</enable_wind>
        <kinematic>0</kinematic>
      </link>
      <link name='camera_rgb_frame'>
        <inertial>
          <pose>0.069 -0.047 0.107 0 -0 0</pose>
          <inertia>
            <ixx>0.001</ixx>
            <ixy>0</ixy>
            <ixz>0</ixz>
            <iyy>0.001</iyy>
            <iyz>0</iyz>
            <izz>0.001</izz>
          </inertia>
          <mass>0.035</mass>
        </inertial>
        <pose>0.069 -0.047 0.107 0 -0 0</pose>
        <sensor name='camera' type='depth'>
          <pose>0 0 0 0 -0 0</pose>
          <always_on>1</always_on>
          <visualize>1</visualize>
          <update_rate>1</update_rate>
          <camera name='intel_realsense_r200'>
            <horizontal_fov>1.02974</horizontal_fov>
            <image>
              <width>640</width>
              <height>480</height>
              <format>B8G8R8</format>
            </image>
            <clip>
              <near>0.05</near>
              <far>8</far>
            </clip>
            <noise>
              <type>gaussian</type>
              <mean>0</mean>
              <stddev>0.007</stddev>
            </noise>
          </camera>
          <plugin name='camera_driver' filename='libgazebo_ros_camera.so'>
            <ros>
              <namespace>/tb1</namespace>
            </ros>
            <frame_name>camera_rgb_frame</frame_name>
            <min_depth>0.1</min_depth>
            <max_depth>100</max_depth>
          </plugin>
        </sensor>
        <self_collide>0</self_collide>
        <enable_wind>0</enable_wind>
        <kinematic>0</kinematic>
      </link>
      <joint name='base_joint' type='fixed'>
        <parent>base_footprint</parent>
        <child>base_link</child>
      </joint>
      <joint name='wheel_left_joint' type='revolute'>
        <parent>base_link</parent>
        <child>wheel_left_link</child>
        <pose>0 0.144 0.023 -1.57 0 0</pose>
        <axis>
          <xyz>0 0 1</xyz>
          <limit>
            <lower>-1e+16</lower>
            <upper>1e+16</upper>
          </limit>
          <dynamics>
            <spring_reference>0</spring_reference>
            <spring_stiffness>0</spring_stiffness>
          </dynamics>
        </axis>
      </joint>
      <joint name='wheel_right_joint' type='revolute'>
        <parent>base_link</parent>
        <child>wheel_right_link</child>
        <pose>0 -0.144 0.023 -1.57 0 0</pose>
        <axis>
          <xyz>0 0 1</xyz>
          <limit>
            <lower>-1e+16</lower>
            <upper>1e+16</upper>
          </limit>
          <dynamics>
            <spring_reference>0</spring_reference>
            <spring_stiffness>0</spring_stiffness>
          </dynamics>
        </axis>
      </joint>
      <joint name='caster_back_right_joint' type='ball'>
        <parent>base_link</parent>
        <child>caster_back_right_link</child>
      </joint>
      <joint name='caster_back_left_joint' type='ball'>
        <parent>base_link</parent>
        <child>caster_back_left_link</child>
      </joint>
      <joint name='imu_joint' type='fixed'>
        <parent>base_link</parent>
        <child>imu_link</child>
        <pose>-0.032 0 0.068 0 -0 0</pose>
        <axis>
          <xyz>0 0 1</xyz>
          <limit>
            <lower>-1e+16</lower>
            <upper>1e+16</upper>
          </limit>
        </axis>
      </joint>
      <joint name='lidar_joint' type='fixed'>
        <parent>base_link</parent>
        <child>base_scan</child>
        <pose>-0.064 0 0.121 0 -0 0</pose>
        <axis>
          <xyz>0 0 1</xyz>
          <limit>
            <lower>-1e+16</lower>
            <upper>1e+16</upper>
          </limit>
        </axis>
      </joint>
      <joint name='camera_joint' type='fixed'>
        <parent>base_link</parent>
        <child>camera_link</child>
        <pose>0.064 -0.065 0.094 0 -0 0</pose>
        <axis>
          <xyz>0 0 1</xyz>
          <limit>
            <lower>-1e+16</lower>
            <upper>1e+16</upper>
          </limit>
        </axis>
      </joint>
      <joint name='camera_rgb_joint' type='fixed'>
        <parent>camera_link</parent>
        <child>camera_rgb_frame</child>
        <pose>0.005 0.018 0.013 1 -0 0</pose>
        <axis>
          <xyz>0 0 1</xyz>
          <limit>
            <lower>-1e+16</lower>
            <upper>1e+16</upper>
          </limit>
        </axis>
      </joint>
      <plugin name='turtlebot3_diff_drive' filename='libgazebo_ros_diff_drive.so'>
        <ros>
          <remapping>/tf:=tf</remapping>
          <namespace>/tb1</namespace>
        </ros>
        <update_rate>30</update_rate>
        <left_joint>wheel_left_joint</left_joint>
        <right_joint>wheel_right_joint</right_joint>
        <wheel_separation>0.287</wheel_separation>
        <wheel_diameter>0.066</wheel_diameter>
        <max_wheel_torque>20</max_wheel_torque>
        <max_wheel_acceleration>1.0</max_wheel_acceleration>
        <command_topic>cmd_vel</command_topic>
        <publish_odom>1</publish_odom>
        <publish_odom_tf>1</publish_odom_tf>
        <publish_wheel_tf>0</publish_wheel_tf>
        <odometry_topic>odom</odometry_topic>
        <odometry_frame>odom</odometry_frame>
        <robot_base_frame>base_footprint</robot_base_frame>
      </plugin>
      <plugin name='turtlebot3_joint_state' filename='libgazebo_ros_joint_state_publisher.so'>
        <ros>
          <remapping>~/out:=joint_states</remapping>
          <namespace>/tb1</namespace>
        </ros>
        <update_rate>30</update_rate>
        <joint_name>wheel_left_joint</joint_name>
        <joint_name>wheel_right_joint</joint_name>
      </plugin>
    </model>
    <model name='tb2'>
      <pose>-1.5 0.5 0.01 0 -0 0</pose>
      <link name='base_footprint'>
        <self_collide>0</self_collide>
        <inertial>
          <pose>0 0 0 0 -0 0</pose>
          <inertia>
            <ixx>1</ixx>
            <ixy>0</ixy>
            <ixz>0</ixz>
            <iyy>1</iyy>
            <iyz>0</iyz>
            <izz>1</izz>
          </inertia>
          <mass>1</mass>
        </inertial>
        <enable_wind>0</enable_wind>
        <kinematic>0</kinematic>
      </link>
      <link name='base_link'>
        <inertial>
          <pose>-0.064 0 0.048 0 -0 0</pose>
          <inertia>
            <ixx>0.0421114</ixx>
            <ixy>0</ixy>
            <ixz>0</ixz>
            <iyy>0.0421114</iyy>
            <iyz>0</iyz>
            <izz>0.0752549</izz>
          </inertia>
          <mass>1.37291</mass>
        </inertial>
        <collision name='base_collision'>
          <pose>-0.064 0 0.048 0 -0 0</pose>
          <geometry>
            <box>
              <size>0.265 0.265 0.089</size>
            </box>
          </geometry>
          <max_contacts>10</max_contacts>
          <surface>
            <contact>
              <ode/>
            </contact>
            <bounce/>
            <friction>
              <torsional>
                <ode/>
              </torsional>
              <ode/>
            </friction>
          </surface>
        </collision>
        <visual name='base_visual'>
          <pose>-0.064 0 0 0 -0 0</pose>
          <geometry>
            <mesh>
              <uri>model://turtlebot3_common/meshes/waffle_base.dae</uri>
              <scale>0.001 0.001 0.001</scale>
            </mesh>
          </geometry>
        </visual>
        <self_collide>0</self_collide>
        <enable_wind>0</enable_wind>
        <kinematic>0</kinematic>
      </link>
      <link name='imu_link'>
        <sensor name='tb3_imu' type='imu'>
          <always_on>1</always_on>
          <update_rate>200</update_rate>
          <imu>
            <angular_velocity>
              <x>
                <noise type='gaussian'>
                  <mean>0</mean>
                  <stddev>0.0002</stddev>
                </noise>
              </x>
              <y>
                <noise type='gaussian'>
                  <mean>0</mean>
                  <stddev>0.0002</stddev>
                </noise>
              </y>
              <z>
                <noise type='gaussian'>
                  <mean>0</mean>
                  <stddev>0.0002</stddev>
                </noise>
              </z>
            </angular_velocity>
            <linear_acceleration>
              <x>
                <noise type='gaussian'>
                  <mean>0</mean>
                  <stddev>0.017</stddev>
                </noise>
              </x>
              <y>
                <noise type='gaussian'>
                  <mean>0</mean>
                  <stddev>0.017</stddev>
                </noise>
              </y>
              <z>
                <noise type='gaussian'>
                  <mean>0</mean>
                  <stddev>0.017</stddev>
                </noise>
              </z>
            </linear_acceleration>
            <angular_velocity/>
            <linear_acceleration/>
          </imu>
          <plugin name='turtlebot3_imu' filename='libgazebo_ros_imu_sensor.so'>
            <ros>
              <remapping>~/out:=imu</remapping>
              <namespace>/tb2</namespace>
            </ros>
          </plugin>
        </sensor>
        <self_collide>0</self_collide>
        <inertial>
          <pose>0 0 0 0 -0 0</pose>
          <inertia>
            <ixx>1</ixx>
            <ixy>0</ixy>
            <ixz>0</ixz>
            <iyy>1</iyy>
            <iyz>0</iyz>
            <izz>1</izz>
          </inertia>
          <mass>1</mass>
        </inertial>
        <enable_wind>0</enable_wind>
        <kinematic>0</kinematic>
      </link>
      <link name='base_scan'>
        <inertial>
          <pose>-0.052 0 0.111 0 -0 0</pose>
          <inertia>
            <ixx>0.001</ixx>
            <ixy>0</ixy>
            <ixz>0</ixz>
            <iyy>0.001</iyy>
            <iyz>0</iyz>
            <izz>0.001</izz>
          </inertia>
          <mass>0.114</mass>
        </inertial>
        <collision name='lidar_sensor_collision'>
          <pose>-0.052 0 0.111 0 -0 0</pose>
          <geometry>
            <cylinder>
              <radius>0.0508</radius>
              <length>0.055</length>
            </cylinder>
          </geometry>
          <max_contacts>10</max_contacts>
          <surface>
            <contact>
              <ode/>
            </contact>
            <bounce/>
            <friction>
              <torsional>
                <ode/>
              </torsional>
              <ode/>
            </friction>
          </surface>
        </collision>
        <visual name='lidar_sensor_visual'>
          <pose>-0.064 0 0.121 0 -0 0</pose>
          <geometry>
            <mesh>
              <uri>model://turtlebot3_common/meshes/lds.dae</uri>
              <scale>0.001 0.001 0.001</scale>
            </mesh>
          </geometry>
        </visual>
        <sensor name='hls_lfcd_lds' type='ray'>
          <always_on>1</always_on>
          <visualize>0</visualize>
          <pose>-0.064 0 0.121 0 -0 0</pose>
          <update_rate>5</update_rate>
          <ray>
            <scan>
              <horizontal>
                <samples>360</samples>
                <resolution>1</resolution>
                <min_angle>0</min_angle>
                <max_angle>6.28</max_angle>
              </horizontal>
              <vertical>
                <samples>1</samples>
                <min_angle>0</min_angle>
                <max_angle>0</max_angle>
              </vertical>
            </scan>
            <range>
              <min>0.12</min>
              <max>3.5</max>
              <resolution>0.015</resolution>
            </range>
            <noise>
              <type>gaussian</type>
              <mean>0</mean>
              <stddev>0.01</stddev>
            </noise>
          </ray>
          <plugin name='turtlebot3_laserscan' filename='libgazebo_ros_ray_sensor.so'>
            <ros>
              <remapping>~/out:=scan</remapping>
              <namespace>/tb2</namespace>
            </ros>
            <output_type>sensor_msgs/LaserScan</output_type>
            <frame_name>base_scan</frame_name>
          </plugin>
        </sensor>
        <self_collide>0</self_collide>
        <enable_wind>0</enable_wind>
        <kinematic>0</kinematic>
      </link>
      <link name='wheel_left_link'>
        <inertial>
          <pose>0 0.144 0.023 -1.57 0 0</pose>
          <inertia>
            <ixx>1.11756e-05</ixx>
            <ixy>-4.23698e-11</ixy>
            <ixz>-5.93817e-09</ixz>
            <iyy>1.11924e-05</iyy>
            <iyz>-1.44001e-11</iyz>
            <izz>2.07126e-05</izz>
          </inertia>
          <mass>0.1</mass>
        </inertial>
        <collision name='wheel_left_collision'>
          <pose>0 0.144 0.023 -1.57 0 0</pose>
          <geometry>
            <cylinder>
              <radius>0.033</radius>
              <length>0.018</length>
            </cylinder>
          </geometry>
          <surface>
            <friction>
              <ode>
                <mu>100000</mu>
                <mu2>100000</mu2>
                <fdir1>0 0 0</fdir1>
                <slip1>0</slip1>
                <slip2>0</slip2>
              </ode>
              <torsional>
                <ode/>
              </torsional>
            </friction>
            <contact>
              <ode>
                <soft_cfm>0</soft_cfm>
                <soft_erp>0.2</soft_erp>
                <kp>100000</kp>
                <kd>1</kd>
                <max_vel>0.01</max_vel>
                <min_depth>0.001</min_depth>
              </ode>
            </contact>
            <bounce/>
          </surface>
          <max_contacts>10</max_contacts>
        </collision>
        <visual name='wheel_left_visual'>
          <pose>0 0.144 0.023 0 -0 0</pose>
          <geometry>
            <mesh>
              <uri>model://turtlebot3_common/meshes/tire.dae</uri>
              <scale>0.001 0.001 0.001</scale>
            </mesh>
          </geometry>
        </visual>
        <self_collide>0</self_collide>
        <enable_wind>0</enable_wind>
        <kinematic>0</kinematic>
      </link>
      <link name='wheel_right_link'>
        <inertial>
          <pose>0 -0.144 0.023 -1.57 0 0</pose>
          <inertia>
            <ixx>1.11756e-05</ixx>
            <ixy>-4.23698e-11</ixy>
            <ixz>-5.93817e-09</ixz>
            <iyy>1.11924e-05</iyy>
            <iyz>-1.44001e-11</iyz>
            <izz>2.07126e-05</izz>
          </inertia>
          <mass>0.1</mass>
        </inertial>
        <collision name='wheel_right_collision'>
          <pose>0 -0.144 0.023 -1.57 0 0</pose>
          <geometry>
            <cylinder>
              <radius>0.033</radius>
              <length>0.018</length>
            </cylinder>
          </geometry>
          <surface>
            <friction>
              <ode>
                <mu>100000</mu>
                <mu2>100000</mu2>
                <fdir1>0 0 0</fdir1>
                <slip1>0</slip1>
                <slip2>0</slip2>
              </ode>
              <torsional>
                <ode/>
              </torsional>
            </friction>
            <contact>
              <ode>
                <soft_cfm>0</soft_cfm>
                <soft_erp>0.2</soft_erp>
                <kp>100000</kp>
                <kd>1</kd>
                <max_vel>0.01</max_vel>
                <min_depth>0.001</min_depth>
              </ode>
            </contact>
            <bounce/>
          </surface>
          <max_contacts>10</max_contacts>
        </collision>
        <visual name='wheel_right_visual'>
          <pose>0 -0.144 0.023 0 -0 0</pose>
          <geometry>
            <mesh>
              <uri>model://turtlebot3_common/meshes/tire.dae</uri>
              <scale>0.001 0.001 0.001</scale>
            </mesh>
          </geometry>
        </visual>
        <self_collide>0</self_collide>
        <enable_wind>0</enable_wind>
        <kinematic>0</kinematic>
      </link>
      <link name='caster_back_right_link'>
        <pose>-0.177 -0.064 -0.004 -1.57 0 0</pose>
        <inertial>
          <mass>0.001</mass>
          <inertia>
            <ixx>1e-05</ixx>
            <ixy>0</ixy>
            <ixz>0</ixz>
            <iyy>1e-05</iyy>
            <iyz>0</iyz>
            <izz>1e-05</izz>
          </inertia>
          <pose>0 0 0 0 -0 0</pose>
        </inertial>
        <collision name='collision'>
          <geometry>
            <sphere>
              <radius>0.005</radius>
            </sphere>
          </geometry>
          <surface>
            <contact>
              <ode>
                <soft_cfm>0</soft_cfm>
                <soft_erp>0.2</soft_erp>
                <kp>100000</kp>
                <kd>1</kd>
                <max_vel>0.01</max_vel>
                <min_depth>0.001</min_depth>
              </ode>
            </contact>
            <bounce/>
            <friction>
              <torsional>
                <ode/>
              </torsional>
              <ode/>
            </friction>
          </surface>
          <max_contacts>10</max_contacts>
        </collision>
        <self_collide>0</self_collide>
        <enable_wind>0</enable_wind>
        <kinematic>0</kinematic>
      </link>
      <link name='caster_back_left_link'>
        <pose>-0.177 0.064 -0.004 -1.57 0 0</pose>
        <inertial>
          <mass>0.001</mass>
          <inertia>
            <ixx>1e-05</ixx>
            <ixy>0</ixy>
            <ixz>0</ixz>
            <iyy>1e-05</iyy>
            <iyz>0</iyz>
            <izz>1e-05</izz>
          </inertia>
          <pose>0 0 0 0 -0 0</pose>
        </inertial>
        <collision name='collision'>
          <geometry>
            <sphere>
              <radius>0.005</radius>
            </sphere>
          </geometry>
          <surface>
            <contact>
              <ode>
                <soft_cfm>0</soft_cfm>
                <soft_erp>0.2</soft_erp>
                <kp>100000</kp>
                <kd>1</kd>
                <max_vel>0.01</max_vel>
                <min_depth>0.001</min_depth>
              </ode>
            </contact>
            <bounce/>
            <friction>
              <torsional>
                <ode/>
              </torsional>
              <ode/>
            </friction>
          </surface>
          <max_contacts>10</max_contacts>
        </collision>
        <self_collide>0</self_collide>
        <enable_wind>0</enable_wind>
        <kinematic>0</kinematic>
      </link>
      <link name='camera_link'>
        <self_collide>0</self_collide>
        <inertial>
          <pose>0 0 0 0 -0 0</pose>
          <inertia>
            <ixx>1</ixx>
            <ixy>0</ixy>
            <ixz>0</ixz>
            <iyy>1</iyy>
            <iyz>0</iyz>
            <izz>1</izz>
          </inertia>
          <mass>1</mass>
        </inertial>
        <enable_wind>0</enable_wind>
        <kinematic>0</kinematic>
      </link>
      <link name='camera_rgb_frame'>
        <inertial>
          <pose>0.069 -0.047 0.107 0 -0 0</pose>
          <inertia>
            <ixx>0.001</ixx>
            <ixy>0</ixy>
            <ixz>0</ixz>
            <iyy>0.001</iyy>
            <iyz>0</iyz>
            <izz>0.001</izz>
          </inertia>
          <mass>0.035</mass>
        </inertial>
        <pose>0.069 -0.047 0.107 0 -0 0</pose>
        <sensor name='camera' type='depth'>
          <pose>0 0 0 0 -0 0</pose>
          <always_on>1</always_on>
          <visualize>1</visualize>
          <update_rate>1</update_rate>
          <camera name='intel_realsense_r200'>
            <horizontal_fov>1.02974</horizontal_fov>
            <image>
              <width>640</width>
              <height>480</height>
              <format>B8G8R8</format>
            </image>
            <clip>
              <near>0.05</near>
              <far>8</far>
            </clip>
            <noise>
              <type>gaussian</type>
              <mean>0</mean>
              <stddev>0.007</stddev>
            </noise>
          </camera>
          <plugin name='camera_driver' filename='libgazebo_ros_camera.so'>
            <ros>
              <namespace>/tb2</namespace>
            </ros>
            <frame_name>camera_rgb_frame</frame_name>
            <min_depth>0.1</min_depth>
            <max_depth>100</max_depth>
          </plugin>
        </sensor>
        <self_collide>0</self_collide>
        <enable_wind>0</enable_wind>
        <kinematic>0</kinematic>
      </link>
      <joint name='base_joint' type='fixed'>
        <parent>base_footprint</parent>
        <child>base_link</child>
      </joint>
      <joint name='wheel_left_joint' type='revolute'>
        <parent>base_link</parent>
        <child>wheel_left_link</child>
        <pose>0 0.144 0.023 -1.57 0 0</pose>
        <axis>
          <xyz>0 0 1</xyz>
          <limit>
            <lower>-1e+16</lower>
            <upper>1e+16</upper>
          </limit>
          <dynamics>
            <spring_reference>0</spring_reference>
            <spring_stiffness>0</spring_stiffness>
          </dynamics>
        </axis>
      </joint>
      <joint name='wheel_right_joint' type='revolute'>
        <parent>base_link</parent>
        <child>wheel_right_link</child>
        <pose>0 -0.144 0.023 -1.57 0 0</pose>
        <axis>
          <xyz>0 0 1</xyz>
          <limit>
            <lower>-1e+16</lower>
            <upper>1e+16</upper>
          </limit>
          <dynamics>
            <spring_reference>0</spring_reference>
            <spring_stiffness>0</spring_stiffness>
          </dynamics>
        </axis>
      </joint>
      <joint name='caster_back_right_joint' type='ball'>
        <parent>base_link</parent>
        <child>caster_back_right_link</child>
      </joint>
      <joint name='caster_back_left_joint' type='ball'>
        <parent>base_link</parent>
        <child>caster_back_left_link</child>
      </joint>
      <joint name='imu_joint' type='fixed'>
        <parent>base_link</parent>
        <child>imu_link</child>
        <pose>-0.032 0 0.068 0 -0 0</pose>
        <axis>
          <xyz>0 0 1</xyz>
          <limit>
            <lower>-1e+16</lower>
            <upper>1e+16</upper>
          </limit>
        </axis>
      </joint>
      <joint name='lidar_joint' type='fixed'>
        <parent>base_link</parent>
        <child>base_scan</child>
        <pose>-0.064 0 0.121 0 -0 0</pose>
        <axis>
          <xyz>0 0 1</xyz>
          <limit>
            <lower>-1e+16</lower>
            <upper>1e+16</upper>
          </limit>
        </axis>
      </joint>
      <joint name='camera_joint' type='fixed'>
        <parent>base_link</parent>
        <child>camera_link</child>
        <pose>0.064 -0.065 0.094 0 -0 0</pose>
        <axis>
          <xyz>0 0 1</xyz>
          <limit>
            <lower>-1e+16</lower>
            <upper>1e+16</upper>
          </limit>
        </axis>
      </joint>
      <joint name='camera_rgb_joint' type='fixed'>
        <parent>camera_link</parent>
        <child>camera_rgb_frame</child>
        <pose>0.005 0.018 0.013 1 -0 0</pose>
        <axis>
          <xyz>0 0 1</xyz>
          <limit>
            <lower>-1e+16</lower>
            <upper>1e+16</upper>
          </limit>
        </axis>
      </joint>
      <plugin name='turtlebot3_diff_drive' filename='libgazebo_ros_diff_drive.so'>
        <ros>
          <remapping>/tf:=tf</remapping>
          <namespace>/tb2</namespace>
        </ros>
        <update_rate>30</update_rate>
        <left_joint>wheel_left_joint</left_joint>
        <right_joint>wheel_right_joint</right_joint>
        <wheel_separation>0.287</wheel_separation>
        <wheel_diameter>0.066</wheel_diameter>
        <max_wheel_torque>20</max_wheel_torque>
        <max_wheel_acceleration>1.0</max_wheel_acceleration>
        <command_topic>cmd_vel</command_topic>
        <publish_odom>1</publish_odom>
        <publish_odom_tf>1</publish_odom_tf>
        <publish_wheel_tf>0</publish_wheel_tf>
        <odometry_topic>odom</odometry_topic>
        <odometry_frame>odom</odometry_frame>
        <robot_base_frame>base_footprint</robot_base_frame>
      </plugin>
      <plugin name='turtlebot3_joint_state' filename='libgazebo_ros_joint_state_publisher.so'>
        <ros>
          <remapping>~/out:=joint_states</remapping>
          <namespace>/tb2</namespace>
        </ros>
        <update_rate>30</update_rate>
        <joint_name>wheel_left_joint</joint_name>
        <joint_name>wheel_right_joint</joint_name>
      </plugin>
    </model>
  </world>
</sdf>
